Workbook

Sheet Portada
B3: BOARD PACK | C3: ='0 · Configuración'!C7
B5: LA ANATOMÍA DE UNA JUNTA, EN SIETE BLOQUES
B8: Plantilla de reporte financiero a junta directiva. Se llena una sola hoja de datos; los siete bloques y el resumen se calculan solos.
B12: 7 | E12: bloques cubren el 90% de lo que una junta mira desde finanzas. El 10% restante es tu criterio — y para eso está la hoja de acciones.
B18: MAURICIO ESCOBAR
B19: Arquitecto de decisiones financieras
B20: Plantilla gratuita. Úsala, edítala, cámbiale los nombres.
B23: POR DÓNDE EMPEZAR
B25: 1 | C25: Abre «0 · Configuración»: nombre de la empresa, tus tres líneas de negocio, tus categorías de gasto y tus umbrales.
B26: 2 | C26: Ve a «1 · Datos» y reemplaza los números de ejemplo. Es la única hoja donde se escribe.
B27: 3 | C27: Las hojas 2 a 7 se calculan solas. Las hojas 8 y 9 se escriben a mano: son criterio, no fórmula.
B28: 4 | C28: Presenta en el orden de las pestañas. Ese orden viene de una junta real, no de un índice.

Sheet 0 · Configuración
B2: CONFIGURACIÓN
B3: Lo que escribas aquí se propaga a todo el archivo. Las celdas sobre panel son las editables.
B5: IDENTIFICACIÓN
B6: Empresa | C6: [NOMBRE DE LA EMPRESA]
B7: Periodo del reporte | C7: Enero – Diciembre 2026
B8: Moneda y unidad | C8: COP, millones | D8: Toda la plantilla usa la misma unidad.
B9: Mes de corte (1 a 12) | C9: 12 | D9: Hasta qué mes hay cifra real. El resumen solo mira hasta ahí.
B11: LÍNEAS DE NEGOCIO | D11: Una junta no mira el consolidado: mira de dónde sale cada margen.
B12: Negocio 1 | C12: Servicios
B13: Negocio 2 | C13: Licenciamiento
B14: Negocio 3 | C14: Proyectos
B16: CATEGORÍAS DE GASTO ADMINISTRATIVO | D16: Seis basta. El detalle de veinte no lo lee nadie.
B17: Categoría 1 | C17: Nómina administrativa
B18: Categoría 2 | C18: Honorarios y asesorías
B19: Categoría 3 | C19: Arriendos y servicios
B20: Categoría 4 | C20: Tecnología y licencias
B21: Categoría 5 | C21: Viajes y representación
B22: Categoría 6 | C22: Otros gastos
B24: UMBRALES | D24: Los define tu política, no la plantilla. Marcan qué se lee como acción pendiente.
B25: Desviación de ingreso tolerada | C25: -0.05 | D25: Por debajo de esto, el bloque pide acción.
B26: Desviación de gasto tolerada | C26: 0.05 | D26: Por encima de esto, el bloque pide acción.
B27: Margen bruto mínimo aceptable | C27: 0.3 | D27: Consolidado y por línea.
B28: Caja mínima de operación | C28: 1500 | D28: En la unidad de arriba.
B29: Apalancamiento máximo (Deuda/EBITDA) | C29: 3 | D29: Covenant o política interna.
B30: Días de cartera objetivo | C30: 45 | D30: También se usa como referencia de proveedores.
B33: Un umbral discutible es infinitamente mejor que ninguno. Su función no es tener razón: es que la junta deje de discutir si algo está mal y pase a discutir qué se hizo.

Sheet 1 · Datos
B2: DATOS
B3: La única hoja donde se escribe. Cifras en millones. Todo lo demás en este archivo se calcula solo.
B5: INGRESOS Y PIPELINE | D5: Alineado con comercial. Si el forecast lo arma finanzas sola, la junta lo va a notar.
B6: LÍNEA DE NEGOCIO | D6: Ene | E6: Feb | F6: Mar | G6: Abr | H6: May | I6: Jun | J6: Jul | K6: Ago | L6: Sep | M6: Oct | N6: Nov | O6: Dic | P6: AÑO
B7: REAL
B8: ='0 · Configuración'!C12 | D8: 1180 | E8: 1210 | F8: 1260 | G8: 1240 | H8: 1300 | I8: 1350 | J8: 1320 | K8: 1380 | L8: 1410 | M8: 1450 | N8: 1490 | O8: 1560 | P8: =SUM(D8:O8)
B9: ='0 · Configuración'!C13 | D9: 820 | E9: 830 | F9: 810 | G9: 850 | H9: 880 | I9: 860 | J9: 900 | K9: 910 | L9: 930 | M9: 950 | N9: 980 | O9: 1020 | P9: =SUM(D9:O9)
B10: ='0 · Configuración'!C14 | D10: 540 | E10: 610 | F10: 580 | G10: 700 | H10: 650 | I10: 720 | J10: 690 | K10: 760 | L10: 800 | M10: 780 | N10: 830 | O10: 910 | P10: =SUM(D10:O10)
B11: Total ingresos | D11: =SUM(D8:D10) | E11: =SUM(E8:E10) | F11: =SUM(F8:F10) | G11: =SUM(G8:G10) | H11: =SUM(H8:H10) | I11: =SUM(I8:I10) | J11: =SUM(J8:J10) | K11: =SUM(K8:K10) | ... O11: =SUM(O8:O10) | P11: =SUM(D11:O11)
B13: PRESUPUESTO
B14: ='0 · Configuración'!C12 | D14: 1200 | E14: 1240 | F14: 1280 | G14: 1300 | H14: 1330 | I14: 1360 | J14: 1390 | K14: 1420 | L14: 1450 | M14: 1480 | N14: 1510 | O14: 1540 | P14: =SUM(D14:O14)
B15: ='0 · Configuración'!C13 | D15: 850 | E15: 860 | F15: 870 | G15: 880 | H15: 890 | I15: 900 | J15: 910 | K15: 920 | L15: 930 | M15: 940 | N15: 950 | O15: 960 | P15: =SUM(D15:O15)
B16: ='0 · Configuración'!C14 | D16: 600 | E16: 620 | F16: 640 | G16: 660 | H16: 680 | I16: 700 | J16: 720 | K16: 740 | L16: 760 | M16: 780 | N16: 800 | O16: 820 | P16: =SUM(D16:O16)
B17: Total presupuestado | D17: =SUM(D14:D16) | E17: =SUM(E14:E16) | F17: =SUM(F14:F16) | G17: =SUM(G14:G16) | H17: =SUM(H14:H16) | I17: =SUM(I14:I16) | J17: =SUM(J14:J16) | K17: =SUM(K14:K16) | ... O17: =SUM(O14:O16) | P17: =SUM(D17:O17)
B19: PIPELINE PONDERADO (COMERCIAL)
B20: ='0 · Configuración'!C12 | D20: 1250 | E20: 1290 | F20: 1330 | G20: 1350 | H20: 1380 | I20: 1410 | J20: 1440 | K20: 1470 | L20: 1500 | M20: 1530 | N20: 1560 | O20: 1600 | P20: =SUM(D20:O20)
B21: ='0 · Configuración'!C13 | D21: 860 | E21: 870 | F21: 880 | G21: 890 | H21: 900 | I21: 910 | J21: 920 | K21: 930 | L21: 940 | M21: 950 | N21: 960 | O21: 970 | P21: =SUM(D21:O21)
B22: ='0 · Configuración'!C14 | D22: 640 | E22: 660 | F22: 690 | G22: 710 | H22: 740 | I22: 760 | J22: 790 | K22: 810 | L22: 840 | M22: 860 | N22: 890 | O22: 910 | P22: =SUM(D22:O22)
B23: Total pipeline | D23: =SUM(D20:D22) | E23: =SUM(E20:E22) | F23: =SUM(F20:F22) | G23: =SUM(G20:G22) | H23: =SUM(H20:H22) | I23: =SUM(I20:I22) | J23: =SUM(J20:J22) | K23: =SUM(K20:K22) | ... O23: =SUM(O20:O22) | P23: =SUM(D23:O23)
B26: COSTO DIRECTO | D26: Solo lo atribuible a cada negocio. Lo demás es gasto administrativo.
B27: LÍNEA DE NEGOCIO | D27: Ene | E27: Feb | F27: Mar | G27: Abr | H27: May | I27: Jun | J27: Jul | K27: Ago | L27: Sep | M27: Oct | N27: Nov | O27: Dic | P27: AÑO
B28: REAL
B29: ='0 · Configuración'!C12 | D29: 732 | E29: 750 | F29: 781 | G29: 769 | H29: 806 | I29: 837 | J29: 818 | K29: 856 | L29: 874 | M29: 899 | N29: 924 | O29: 967 | P29: =SUM(D29:O29)
B30: ='0 · Configuración'!C13 | D30: 287 | E30: 290 | F30: 284 | G30: 298 | H30: 308 | I30: 301 | J30: 315 | K30: 318 | L30: 326 | M30: 332 | N30: 343 | O30: 357 | P30: =SUM(D30:O30)
B31: ='0 · Configuración'!C14 | D31: 400 | E31: 451 | F31: 429 | G31: 518 | H31: 481 | I31: 533 | J31: 511 | K31: 562 | L31: 592 | M31: 577 | N31: 614 | O31: 673 | P31: =SUM(D31:O31)
B32: Total costo directo | D32: =SUM(D29:D31) | E32: =SUM(E29:E31) | F32: =SUM(F29:F31) | G32: =SUM(G29:G31) | H32: =SUM(H29:H31) | I32: =SUM(I29:I31) | J32: =SUM(J29:J31) | K32: =SUM(K29:K31) | ... O32: =SUM(O29:O31) | P32: =SUM(D32:O32)
B34: PRESUPUESTO
B35: ='0 · Configuración'!C12 | D35: 720 | E35: 744 | F35: 768 | G35: 780 | H35: 798 | I35: 816 | J35: 834 | K35: 852 | L35: 870 | M35: 888 | N35: 906 | O35: 924 | P35: =SUM(D35:O35)
B36: ='0 · Configuración'!C13 | D36: 298 | E36: 301 | F36: 304 | G36: 308 | H36: 312 | I36: 315 | J36: 318 | K36: 322 | L36: 326 | M36: 329 | N36: 332 | O36: 336 | P36: =SUM(D36:O36)
B37: ='0 · Configuración'!C14 | D37: 420 | E37: 434 | F37: 448 | G37: 462 | H37: 476 | I37: 490 | J37: 504 | K37: 518 | L37: 532 | M37: 546 | N37: 560 | O37: 574 | P37: =SUM(D37:O37)
B38: Total costo presupuestado | D38: =SUM(D35:D37) | E38: =SUM(E35:E37) | F38: =SUM(F35:F37) | G38: =SUM(G35:G37) | H38: =SUM(H35:H37) | I38: =SUM(I35:I37) | J38: =SUM(J35:J37) | K38: =SUM(K35:K37) | ... O38: =SUM(O35:O37) | P38: =SUM(D38:O38)
B41: GASTO ADMINISTRATIVO | D41: Seis categorías. El detalle de veinte no lo lee nadie.
B42: CATEGORÍA | D42: Ene | E42: Feb | F42: Mar | G42: Abr | H42: May | I42: Jun | J42: Jul | K42: Ago | L42: Sep | M42: Oct | N42: Nov | O42: Dic | P42: AÑO
B43: REAL
B44: ='0 · Configuración'!C17 | D44: 382 | E44: 384 | F44: 388 | G44: 391 | H44: 395 | I44: 398 | J44: 402 | K44: 405 | L44: 409 | M44: 412 | N44: 416 | O44: 448 | P44: =SUM(D44:O44)
B45: ='0 · Configuración'!C18 | D45: 58 | E45: 62 | F45: 71 | G45: 60 | H45: 64 | I45: 88 | J45: 61 | K45: 63 | L45: 67 | M45: 72 | N45: 69 | O45: 95 | P45: =SUM(D45:O45)
B46: ='0 · Configuración'!C19 | D46: 45 | E46: 45 | F46: 45 | G46: 46 | H46: 46 | I46: 46 | J46: 47 | K46: 47 | L46: 47 | M46: 48 | N46: 48 | O46: 48 | P46: =SUM(D46:O46)
B47: ='0 · Configuración'!C20 | D47: 52 | E47: 54 | F47: 58 | G47: 61 | H47: 63 | I47: 66 | J47: 69 | K47: 72 | L47: 74 | M47: 77 | N47: 80 | O47: 83 | P47: =SUM(D47:O47)
B48: ='0 · Configuración'!C21 | D48: 18 | E48: 24 | F48: 31 | G48: 22 | H48: 27 | I48: 35 | J48: 20 | K48: 26 | L48: 33 | M48: 29 | N48: 24 | O48: 38 | P48: =SUM(D48:O48)
B49: ='0 · Configuración'!C22 | D49: 16 | E49: 19 | F49: 21 | G49: 17 | H49: 22 | I49: 25 | J49: 18 | K49: 20 | L49: 23 | M49: 21 | N49: 19 | O49: 34 | P49: =SUM(D49:O49)
...

Sheet 2 · Resumen junta
B2: RESUMEN PARA LA JUNTA
B3: Una hoja. Si la junta solo mira una, que sea esta. Todo se calcula del mes 1 al mes de corte.
B5: LOS SEIS NÚMEROS | D5: Acumulado del año hasta el mes de corte.
B7: INGRESOS | D7: MARGEN BRUTO | F7: EBITDA | H7: CAJA AL CIERRE | J7: APALANCAMIENTO | L7: DÍAS DE CARTERA
B8: =IF(N(INDEX('1 · Datos'!$D$11:$O$11,'0 · Configuración'!$C$9))=0,"—",IFERROR(SUM(OFFSET('1 · Datos'!$D$11,0,0,1,'0 · Configuración'!$C$9)),"—")) | D8: =IF(N(INDEX('1 · Datos'!$D$11:$O$11,'0 · Configuración'!$C$9))=0,"—",IFERROR(IFERROR(1-SUM(OFFSET('1 · Datos'!$D$32,0,0,1,'0 · Configuración'!$C$9))/SUM(OFFSET('1 · Datos'!$D$11,0,0,1,'0 · Configuración'!$C$9)),0),"—")) | F8: =IF(N(INDEX('1 · Datos'!$D$11:$O$11,'0 · Configuración'!$C$9))=0,"—",IFERROR((SUM(OFFSET('1 · Datos'!$D$11,0,0,1,'0 · Configuración'!$C$9))-SUM(OFFSET('1 · Datos'!$D$32,0,0,1,'0 · Configuración'!$C$9))-SUM(OFFSET('1 · Datos'!$D$50,0,0,1,'0 · Configuración'!$C$9))),"—")) | H8: =IF(N(INDEX('1 · Datos'!$D$11:$O$11,'0 · Configuración'!$C$9))=0,"—",IFERROR(INDEX('1 · Datos'!$D$71:$O$71,'0 · Configuración'!$C$9),"—")) | J8: =IF(N(INDEX('1 · Datos'!$D$11:$O$11,'0 · Configuración'!$C$9))=0,"—",IFERROR(IFERROR(INDEX('1 · Datos'!$D$72:$O$72,'0 · Configuración'!$C$9)/((SUM(OFFSET('1 · Datos'!$D$11,0,0,1,'0 · Configuración'!$C$9))-SUM(OFFSET('1 · Datos'!$D$32,0,0,1,'0 · Configuración'!$C$9))-SUM(OFFSET('1 · Datos'!$D$50,0,0,1,'0 · Configuración'!$C$9)))/'0 · Configuración'!$C$9*12),0),"—")) | L8: =IF(N(INDEX('1 · Datos'!$D$11:$O$11,'0 · Configuración'!$C$9))=0,"—",IFERROR(IFERROR(INDEX('1 · Datos'!$D$80:$O$80,'0 · Configuración'!$C$9)/(SUM(OFFSET('1 · Datos'!$D$11,0,0,1,'0 · Configuración'!$C$9))/'0 · Configuración'!$C$9/30),0),"—"))
B9: =IF(N(INDEX('1 · Datos'!$D$11:$O$11,'0 · Configuración'!$C$9))=0,"—",IFERROR(IFERROR(SUM(OFFSET('1 · Datos'!$D$11,0,0,1,'0 · Configuración'!$C$9))/SUM(OFFSET('1 · Datos'!$D$17,0,0,1,'0 · Configuración'!$C$9))-1,0),"—")) | D9: =IF(N(INDEX('1 · Datos'!$D$11:$O$11,'0 · Configuración'!$C$9))=0,"—",IFERROR(IFERROR((1-SUM(OFFSET('1 · Datos'!$D$32,0,0,1,'0 · Configuración'!$C$9))/SUM(OFFSET('1 · Datos'!$D$11,0,0,1,'0 · Configuración'!$C$9))-'0 · Configuración'!$C$27)*100,0),"—")) | F9: =IF(N(INDEX('1 · Datos'!$D$11:$O$11,'0 · Configuración'!$C$9))=0,"—",IFERROR(IFERROR((SUM(OFFSET('1 · Datos'!$D$11,0,0,1,'0 · Configuración'!$C$9))-SUM(OFFSET('1 · Datos'!$D$32,0,0,1,'0 · Configuración'!$C$9))-SUM(OFFSET('1 · Datos'!$D$50,0,0,1,'0 · Configuración'!$C$9)))/SUM(OFFSET('1 · Datos'!$D$11,0,0,1,'0 · Configuración'!$C$9)),0),"—")) | H9: =IF(N(INDEX('1 · Datos'!$D$11:$O$11,'0 · Configuración'!$C$9))=0,"—",IFERROR(IFERROR(INDEX('1 · Datos'!$D$71:$O$71,'0 · Configuración'!$C$9)/'0 · Configuración'!$C$28-1,0),"—")) | J9: =IF(N(INDEX('1 · Datos'!$D$11:$O$11,'0 · Configuración'!$C$9))=0,"—",IFERROR(IFERROR('0 · Configuración'!$C$29-INDEX('1 · Datos'!$D$72:$O$72,'0 · Configuración'!$C$9)/((SUM(OFFSET('1 · Datos'!$D$11,0,0,1,'0 · Configuración'!$C$9))-SUM(OFFSET('1 · Datos'!$D$32,0,0,1,'0 · Configuración'!$C$9))-SUM(OFFSET('1 · Datos'!$D$50,0,0,1,'0 · Configuración'!$C$9)))/'0 · Configuración'!$C$9*12),0),"—")) | L9: =IF(N(INDEX('1 · Datos'!$D$11:$O$11,'0 · Configuración'!$C$9))=0,"—",IFERROR(IFERROR('0 · Configuración'!$C$30-INDEX('1 · Datos'!$D$80:$O$80,'0 · Configuración'!$C$9)/(SUM(OFFSET('1 · Datos'!$D$11,0,0,1,'0 · Configuración'!$C$9))/'0 · Configuración'!$C$9/30),0),"—"))
B10: vs. presupuesto | D10: vs. mínimo aceptable | F10: margen EBITDA | H10: vs. caja mínima | J10: holgura vs. máximo | L10: holgura vs. objetivo
B13: LOS SIETE BLOQUES | D13: El orden en que se presentan. Ninguno se salta.
B15: BLOQUE | D15: CIFRA CLAVE | F15: REAL | G15: REFERENCIA | H15: DESVIACIÓN | I15: LECTURA
B16: 1 · Ingresos y pipeline | D16: Ingreso acumulado | F16: =IF(N(INDEX('1 · Datos'!$D$11:$O$11,'0 · Configuración'!$C$9))=0,"—",IFERROR(SUM(OFFSET('1 · Datos'!$D$11,0,0,1,'0 · Configuración'!$C$9)),"—")) | G16: =SUM(OFFSET('1 · Datos'!$D$17,0,0,1,'0 · Configuración'!$C$9)) | H16: =IF(NOT(ISNUMBER(F16)),"—",IFERROR(F16/G16-1,"—")) | I16: =IF(NOT(ISNUMBER(H16)),"Sin datos en el período — no concluir",IF(H16>=0,"En línea — sin acción pendiente","Requiere acción — ver hoja 8"))
B17: 2 · Márgenes brutos | D17: Margen bruto consolidado | F17: =IF(N(INDEX('1 · Datos'!$D$11:$O$11,'0 · Configuración'!$C$9))=0,"—",IFERROR(IFERROR(1-SUM(OFFSET('1 · Datos'!$D$32,0,0,1,'0 · Configuración'!$C$9))/SUM(OFFSET('1 · Datos'!$D$11,0,0,1,'0 · Configuración'!$C$9)),0),"—")) | G17: ='0 · Configuración'!$C$27 | H17: =IF(NOT(ISNUMBER(F17)),"—",IFERROR((F17-G17)*100,"—")) | I17: =IF(NOT(ISNUMBER(H17)),"Sin datos en el período — no concluir",IF(H17>=0,"En línea — sin acción pendiente","Requiere acción — ver hoja 8"))
B18: 3 · Gasto administrativo | D18: Gasto acumulado | F18: =IF(N(INDEX('1 · Datos'!$D$11:$O$11,'0 · Configuración'!$C$9))=0,"—",IFERROR(SUM(OFFSET('1 · Datos'!$D$50,0,0,1,'0 · Configuración'!$C$9)),"—")) | G18: =SUM(OFFSET('1 · Datos'!$D$59,0,0,1,'0 · Configuración'!$C$9)) | H18: =IF(NOT(ISNUMBER(F18)),"—",IFERROR(F18/G18-1,"—")) | I18: =IF(NOT(ISNUMBER(H18)),"Sin datos en el período — no concluir",IF(H18<=0,"En línea — sin acción pendiente","Requiere acción — ver hoja 8"))
B19: 4 · Coberturas de divisa | D19: Exposición USD cubierta | F19: =IF(N(INDEX('1 · Datos'!$D$11:$O$11,'0 · Configuración'!$C$9))=0,"—",IFERROR(IFERROR(INDEX('1 · Datos'!$D$75:$O$75,'0 · Configuración'!$C$9)/INDEX('1 · Datos'!$D$74:$O$74,'0 · Configuración'!$C$9),0),"—")) | G19: =1 | H19: =IF(NOT(ISNUMBER(F19)),"—",IFERROR((F19-G19)*100,"—")) | I19: =IF(NOT(ISNUMBER(H19)),"Sin datos en el período — no concluir",IF(H19>=0,"En línea — sin acción pendiente","Requiere acción — ver hoja 8"))
B20: 5 · Caja y deuda | D20: Saldo de caja al cierre | F20: =IF(N(INDEX('1 · Datos'!$D$11:$O$11,'0 · Configuración'!$C$9))=0,"—",IFERROR(INDEX('1 · Datos'!$D$71:$O$71,'0 · Configuración'!$C$9),"—")) | G20: ='0 · Configuración'!$C$28 | H20: =IF(NOT(ISNUMBER(F20)),"—",IFERROR(F20/G20-1,"—")) | I20: =IF(NOT(ISNUMBER(H20)),"Sin datos en el período — no concluir",IF(H20>=0,"En línea — sin acción pendiente","Requiere acción — ver hoja 8"))
B21: 6 · Cartera | D21: Días de cartera | F21: =IF(N(INDEX('1 · Datos'!$D$11:$O$11,'0 · Configuración'!$C$9))=0,"—",IFERROR(IFERROR(INDEX('1 · Datos'!$D$80:$O$80,'0 · Configuración'!$C$9)/(SUM(OFFSET('1 · Datos'!$D$11,0,0,1,'0 · Configuración'!$C$9))/'0 · Configuración'!$C$9/30),0),"—")) | G21: ='0 · Configuración'!$C$30 | H21: =IF(NOT(ISNUMBER(F21)),"—",IFERROR(F21-G21,"—")) | I21: =IF(NOT(ISNUMBER(H21)),"Sin datos en el período — no concluir",IF(H21<=0,"En línea — sin acción pendiente","Requiere acción — ver hoja 8"))
B22: 7 · Proveedores | D22: Días de proveedores | F22: =IF(N(INDEX('1 · Datos'!$D$11:$O$11,'0 · Configuración'!$C$9))=0,"—",IFERROR(IFERROR(INDEX('1 · Datos'!$D$82:$O$82,'0 · Configuración'!$C$9)/(SUM(OFFSET('1 · Datos'!$D$83,0,0,1,'0 · Configuración'!$C$9))/'0 · Configuración'!$C$9/30),0),"—")) | G22: ='0 · Configuración'!$C$30 | H22: =IF(NOT(ISNUMBER(F22)),"—",IFERROR(F22-G22,"—")) | I22: =IF(NOT(ISNUMBER(H22)),"Sin datos en el período — no concluir",IF(H22>=0,"En línea — sin acción pendiente","Requiere acción — ver hoja 8"))
B25: Uno como directivo no puede garantizar que nada malo pase, pero sí que se están tomando acciones al respecto. Por eso la hoja 8 no es opcional: una mala cifra sin dueño es lo único que una junta no perdona.

Sheet 3 · Ingresos y pipeline
B2: INGRESOS Y PIPELINE
B3: El primer bloque de la presentación. La junta pregunta por el pipeline antes que por el ingreso.
B5: CONCEPTO | D5: Ene | E5: Feb | F5: Mar | G5: Abr | H5: May | I5: Jun | J5: Jul | K5: Ago | L5: Sep | M5: Oct | N5: Nov | O5: Dic | P5: AÑO
B6: INGRESO REAL POR LÍNEA
B7: ='0 · Configuración'!C12 | D7: ='1 · Datos'!D8 | E7: ='1 · Datos'!E8 | F7: ='1 · Datos'!F8 | G7: ='1 · Datos'!G8 | H7: ='1 · Datos'!H8 | I7: ='1 · Datos'!I8 | J7: ='1 · Datos'!J8 | K7: ='1 · Datos'!K8 | ... O7: ='1 · Datos'!O8 | P7: =IF(N(INDEX('1 · Datos'!$D$11:$O$11,'0 · Configuración'!$C$9))=0,"—",IFERROR(SUM(OFFSET(D7,0,0,1,'0 · Configuración'!$C$9)),"—"))
B8: ='0 · Configuración'!C13 | D8: ='1 · Datos'!D9 | E8: ='1 · Datos'!E9 | F8: ='1 · Datos'!F9 | G8: ='1 · Datos'!G9 | H8: ='1 · Datos'!H9 | I8: ='1 · Datos'!I9 | J8: ='1 · Datos'!J9 | K8: ='1 · Datos'!K9 | ... O8: ='1 · Datos'!O9 | P8: =IF(N(INDEX('1 · Datos'!$D$11:$O$11,'0 · Configuración'!$C$9))=0,"—",IFERROR(SUM(OFFSET(D8,0,0,1,'0 · Configuración'!$C$9)),"—"))
B9: ='0 · Configuración'!C14 | D9: ='1 · Datos'!D10 | E9: ='1 · Datos'!E10 | F9: ='1 · Datos'!F10 | G9: ='1 · Datos'!G10 | H9: ='1 · Datos'!H10 | I9: ='1 · Datos'!I10 | J9: ='1 · Datos'!J10 | K9: ='1 · Datos'!K10 | ... O9: ='1 · Datos'!O10 | P9: =IF(N(INDEX('1 · Datos'!$D$11:$O$11,'0 · Configuración'!$C$9))=0,"—",IFERROR(SUM(OFFSET(D9,0,0,1,'0 · Configuración'!$C$9)),"—"))
B10: Total ingresos reales | D10: ='1 · Datos'!D11 | E10: ='1 · Datos'!E11 | F10: ='1 · Datos'!F11 | G10: ='1 · Datos'!G11 | H10: ='1 · Datos'!H11 | I10: ='1 · Datos'!I11 | J10: ='1 · Datos'!J11 | K10: ='1 · Datos'!K11 | ... O10: ='1 · Datos'!O11 | P10: =IF(N(INDEX('1 · Datos'!$D$11:$O$11,'0 · Configuración'!$C$9))=0,"—",IFERROR(SUM(OFFSET(D10,0,0,1,'0 · Configuración'!$C$9)),"—"))
B11: CONTRA PRESUPUESTO
B12: Presupuesto | D12: ='1 · Datos'!D17 | E12: ='1 · Datos'!E17 | F12: ='1 · Datos'!F17 | G12: ='1 · Datos'!G17 | H12: ='1 · Datos'!H17 | I12: ='1 · Datos'!I17 | J12: ='1 · Datos'!J17 | K12: ='1 · Datos'!K17 | ... O12: ='1 · Datos'!O17 | P12: =IF(N(INDEX('1 · Datos'!$D$11:$O$11,'0 · Configuración'!$C$9))=0,"—",IFERROR(SUM(OFFSET(D12,0,0,1,'0 · Configuración'!$C$9)),"—"))
B13: Desviación | D13: ='1 · Datos'!D11-'1 · Datos'!D17 | E13: ='1 · Datos'!E11-'1 · Datos'!E17 | F13: ='1 · Datos'!F11-'1 · Datos'!F17 | G13: ='1 · Datos'!G11-'1 · Datos'!G17 | H13: ='1 · Datos'!H11-'1 · Datos'!H17 | I13: ='1 · Datos'!I11-'1 · Datos'!I17 | J13: ='1 · Datos'!J11-'1 · Datos'!J17 | K13: ='1 · Datos'!K11-'1 · Datos'!K17 | ... O13: ='1 · Datos'!O11-'1 · Datos'!O17 | P13: =IF(N(INDEX('1 · Datos'!$D$11:$O$11,'0 · Configuración'!$C$9))=0,"—",IFERROR(SUM(OFFSET(D13,0,0,1,'0 · Configuración'!$C$9)),"—"))
B14: Cumplimiento | D14: =IFERROR('1 · Datos'!D11/'1 · Datos'!D17,0) | E14: =IFERROR('1 · Datos'!E11/'1 · Datos'!E17,0) | F14: =IFERROR('1 · Datos'!F11/'1 · Datos'!F17,0) | G14: =IFERROR('1 · Datos'!G11/'1 · Datos'!G17,0) | H14: =IFERROR('1 · Datos'!H11/'1 · Datos'!H17,0) | I14: =IFERROR('1 · Datos'!I11/'1 · Datos'!I17,0) | J14: =IFERROR('1 · Datos'!J11/'1 · Datos'!J17,0) | K14: =IFERROR('1 · Datos'!K11/'1 · Datos'!K17,0) | ... O14: =IFERROR('1 · Datos'!O11/'1 · Datos'!O17,0) | P14: =IF(N(INDEX('1 · Datos'!$D$11:$O$11,'0 · Configuración'!$C$9))=0,"—",IFERROR(SUM(OFFSET('1 · Datos'!$D$11,0,0,1,'0 · Configuración'!$C$9))/SUM(OFFSET('1 · Datos'!$D$17,0,0,1,'0 · Configuración'!$C$9)),"—"))
B15: PIPELINE PONDERADO DE COMERCIAL
B16: Pipeline | D16: ='1 · Datos'!D23 | E16: ='1 · Datos'!E23 | F16: ='1 · Datos'!F23 | G16: ='1 · Datos'!G23 | H16: ='1 · Datos'!H23 | I16: ='1 · Datos'!I23 | J16: ='1 · Datos'!J23 | K16: ='1 · Datos'!K23 | ... O16: ='1 · Datos'!O23 | P16: =IF(N(INDEX('1 · Datos'!$D$11:$O$11,'0 · Configuración'!$C$9))=0,"—",IFERROR(SUM(OFFSET(D16,0,0,1,'0 · Configuración'!$C$9)),"—"))
B17: Cobertura del presupuesto | D17: =IFERROR('1 · Datos'!D23/'1 · Datos'!D17,0) | E17: =IFERROR('1 · Datos'!E23/'1 · Datos'!E17,0) | F17: =IFERROR('1 · Datos'!F23/'1 · Datos'!F17,0) | G17: =IFERROR('1 · Datos'!G23/'1 · Datos'!G17,0) | H17: =IFERROR('1 · Datos'!H23/'1 · Datos'!H17,0) | I17: =IFERROR('1 · Datos'!I23/'1 · Datos'!I17,0) | J17: =IFERROR('1 · Datos'!J23/'1 · Datos'!J17,0) | K17: =IFERROR('1 · Datos'!K23/'1 · Datos'!K17,0) | ... O17: =IFERROR('1 · Datos'!O23/'1 · Datos'!O17,0) | P17: =IF(N(INDEX('1 · Datos'!$D$11:$O$11,'0 · Configuración'!$C$9))=0,"—",IFERROR(SUM(OFFSET('1 · Datos'!$D$23,0,0,1,'0 · Configuración'!$C$9))/SUM(OFFSET('1 · Datos'!$D$17,0,0,1,'0 · Configuración'!$C$9)),"—"))

Sheet 4 · Márgenes por negocio
B2: MÁRGENES BRUTOS POR NEGOCIO
B3: El consolidado esconde el problema. La junta quiere ver cuál línea lo está causando.
B5: CONCEPTO | D5: Ene | E5: Feb | F5: Mar | G5: Abr | H5: May | I5: Jun | J5: Jul | K5: Ago | L5: Sep | M5: Oct | N5: Nov | O5: Dic | P5: AÑO
B6: MARGEN BRUTO POR LÍNEA (VALOR)
B7: ='0 · Configuración'!C12 | D7: ='1 · Datos'!D8-'1 · Datos'!D29 | E7: ='1 · Datos'!E8-'1 · Datos'!E29 | F7: ='1 · Datos'!F8-'1 · Datos'!F29 | G7: ='1 · Datos'!G8-'1 · Datos'!G29 | H7: ='1 · Datos'!H8-'1 · Datos'!H29 | I7: ='1 · Datos'!I8-'1 · Datos'!I29 | J7: ='1 · Datos'!J8-'1 · Datos'!J29 | K7: ='1 · Datos'!K8-'1 · Datos'!K29 | ... O7: ='1 · Datos'!O8-'1 · Datos'!O29 | P7: =IF(N(INDEX('1 · Datos'!$D$11:$O$11,'0 · Configuración'!$C$9))=0,"—",IFERROR(SUM(OFFSET(D7,0,0,1,'0 · Configuración'!$C$9)),"—"))
B8: ='0 · Configuración'!C13 | D8: ='1 · Datos'!D9-'1 · Datos'!D30 | E8: ='1 · Datos'!E9-'1 · Datos'!E30 | F8: ='1 · Datos'!F9-'1 · Datos'!F30 | G8: ='1 · Datos'!G9-'1 · Datos'!G30 | H8: ='1 · Datos'!H9-'1 · Datos'!H30 | I8: ='1 · Datos'!I9-'1 · Datos'!I30 | J8: ='1 · Datos'!J9-'1 · Datos'!J30 | K8: ='1 · Datos'!K9-'1 · Datos'!K30 | ... O8: ='1 · Datos'!O9-'1 · Datos'!O30 | P8: =IF(N(INDEX('1 · Datos'!$D$11:$O$11,'0 · Configuración'!$C$9))=0,"—",IFERROR(SUM(OFFSET(D8,0,0,1,'0 · Configuración'!$C$9)),"—"))
B9: ='0 · Configuración'!C14 | D9: ='1 · Datos'!D10-'1 · Datos'!D31 | E9: ='1 · Datos'!E10-'1 · Datos'!E31 | F9: ='1 · Datos'!F10-'1 · Datos'!F31 | G9: ='1 · Datos'!G10-'1 · Datos'!G31 | H9: ='1 · Datos'!H10-'1 · Datos'!H31 | I9: ='1 · Datos'!I10-'1 · Datos'!I31 | J9: ='1 · Datos'!J10-'1 · Datos'!J31 | K9: ='1 · Datos'!K10-'1 · Datos'!K31 | ... O9: ='1 · Datos'!O10-'1 · Datos'!O31 | P9: =IF(N(INDEX('1 · Datos'!$D$11:$O$11,'0 · Configuración'!$C$9))=0,"—",IFERROR(SUM(OFFSET(D9,0,0,1,'0 · Configuración'!$C$9)),"—"))
B10: Margen bruto total | D10: ='1 · Datos'!D11-'1 · Datos'!D32 | E10: ='1 · Datos'!E11-'1 · Datos'!E32 | F10: ='1 · Datos'!F11-'1 · Datos'!F32 | G10: ='1 · Datos'!G11-'1 · Datos'!G32 | H10: ='1 · Datos'!H11-'1 · Datos'!H32 | I10: ='1 · Datos'!I11-'1 · Datos'!I32 | J10: ='1 · Datos'!J11-'1 · Datos'!J32 | K10: ='1 · Datos'!K11-'1 · Datos'!K32 | ... O10: ='1 · Datos'!O11-'1 · Datos'!O32 | P10: =IF(N(INDEX('1 · Datos'!$D$11:$O$11,'0 · Configuración'!$C$9))=0,"—",IFERROR(SUM(OFFSET(D10,0,0,1,'0 · Configuración'!$C$9)),"—"))
B11: MARGEN BRUTO POR LÍNEA (%)
B12: ='0 · Configuración'!C12 | D12: =IFERROR(1-'1 · Datos'!D29/'1 · Datos'!D8,0) | E12: =IFERROR(1-'1 · Datos'!E29/'1 · Datos'!E8,0) | F12: =IFERROR(1-'1 · Datos'!F29/'1 · Datos'!F8,0) | G12: =IFERROR(1-'1 · Datos'!G29/'1 · Datos'!G8,0) | H12: =IFERROR(1-'1 · Datos'!H29/'1 · Datos'!H8,0) | I12: =IFERROR(1-'1 · Datos'!I29/'1 · Datos'!I8,0) | J12: =IFERROR(1-'1 · Datos'!J29/'1 · Datos'!J8,0) | K12: =IFERROR(1-'1 · Datos'!K29/'1 · Datos'!K8,0) | ... O12: =IFERROR(1-'1 · Datos'!O29/'1 · Datos'!O8,0) | P12: =IF(N(INDEX('1 · Datos'!$D$11:$O$11,'0 · Configuración'!$C$9))=0,"—",IFERROR(1-SUM(OFFSET('1 · Datos'!$D$29,0,0,1,'0 · Configuración'!$C$9))/SUM(OFFSET('1 · Datos'!$D$8,0,0,1,'0 · Configuración'!$C$9)),"—"))
B13: ='0 · Configuración'!C13 | D13: =IFERROR(1-'1 · Datos'!D30/'1 · Datos'!D9,0) | E13: =IFERROR(1-'1 · Datos'!E30/'1 · Datos'!E9,0) | F13: =IFERROR(1-'1 · Datos'!F30/'1 · Datos'!F9,0) | G13: =IFERROR(1-'1 · Datos'!G30/'1 · Datos'!G9,0) | H13: =IFERROR(1-'1 · Datos'!H30/'1 · Datos'!H9,0) | I13: =IFERROR(1-'1 · Datos'!I30/'1 · Datos'!I9,0) | J13: =IFERROR(1-'1 · Datos'!J30/'1 · Datos'!J9,0) | K13: =IFERROR(1-'1 · Datos'!K30/'1 · Datos'!K9,0) | ... O13: =IFERROR(1-'1 · Datos'!O30/'1 · Datos'!O9,0) | P13: =IF(N(INDEX('1 · Datos'!$D$11:$O$11,'0 · Configuración'!$C$9))=0,"—",IFERROR(1-SUM(OFFSET('1 · Datos'!$D$30,0,0,1,'0 · Configuración'!$C$9))/SUM(OFFSET('1 · Datos'!$D$9,0,0,1,'0 · Configuración'!$C$9)),"—"))
B14: ='0 · Configuración'!C14 | D14: =IFERROR(1-'1 · Datos'!D31/'1 · Datos'!D10,0) | E14: =IFERROR(1-'1 · Datos'!E31/'1 · Datos'!E10,0) | F14: =IFERROR(1-'1 · Datos'!F31/'1 · Datos'!F10,0) | G14: =IFERROR(1-'1 · Datos'!G31/'1 · Datos'!G10,0) | H14: =IFERROR(1-'1 · Datos'!H31/'1 · Datos'!H10,0) | I14: =IFERROR(1-'1 · Datos'!I31/'1 · Datos'!I10,0) | J14: =IFERROR(1-'1 · Datos'!J31/'1 · Datos'!J10,0) | K14: =IFERROR(1-'1 · Datos'!K31/'1 · Datos'!K10,0) | ... O14: =IFERROR(1-'1 · Datos'!O31/'1 · Datos'!O10,0) | P14: =IF(N(INDEX('1 · Datos'!$D$11:$O$11,'0 · Configuración'!$C$9))=0,"—",IFERROR(1-SUM(OFFSET('1 · Datos'!$D$31,0,0,1,'0 · Configuración'!$C$9))/SUM(OFFSET('1 · Datos'!$D$10,0,0,1,'0 · Configuración'!$C$9)),"—"))
B15: Margen bruto consolidado | D15: =IFERROR(1-'1 · Datos'!D32/'1 · Datos'!D11,0) | E15: =IFERROR(1-'1 · Datos'!E32/'1 · Datos'!E11,0) | F15: =IFERROR(1-'1 · Datos'!F32/'1 · Datos'!F11,0) | G15: =IFERROR(1-'1 · Datos'!G32/'1 · Datos'!G11,0) | H15: =IFERROR(1-'1 · Datos'!H32/'1 · Datos'!H11,0) | I15: =IFERROR(1-'1 · Datos'!I32/'1 · Datos'!I11,0) | J15: =IFERROR(1-'1 · Datos'!J32/'1 · Datos'!J11,0) | K15: =IFERROR(1-'1 · Datos'!K32/'1 · Datos'!K11,0) | ... O15: =IFERROR(1-'1 · Datos'!O32/'1 · Datos'!O11,0) | P15: =IF(N(INDEX('1 · Datos'!$D$11:$O$11,'0 · Configuración'!$C$9))=0,"—",IFERROR(1-SUM(OFFSET('1 · Datos'!$D$32,0,0,1,'0 · Configuración'!$C$9))/SUM(OFFSET('1 · Datos'!$D$11,0,0,1,'0 · Configuración'!$C$9)),"—"))
B16: Mínimo aceptable | D16: ='0 · Configuración'!$C$27 | E16: ='0 · Configuración'!$C$27 | F16: ='0 · Configuración'!$C$27 | G16: ='0 · Configuración'!$C$27 | H16: ='0 · Configuración'!$C$27 | I16: ='0 · Configuración'!$C$27 | J16: ='0 · Configuración'!$C$27 | K16: ='0 · Configuración'!$C$27 | ... O16: ='0 · Configuración'!$C$27
B17: EBITDA
B18: EBITDA | D18: ='1 · Datos'!D11-'1 · Datos'!D32-'1 · Datos'!D50 | E18: ='1 · Datos'!E11-'1 · Datos'!E32-'1 · Datos'!E50 | F18: ='1 · Datos'!F11-'1 · Datos'!F32-'1 · Datos'!F50 | G18: ='1 · Datos'!G11-'1 · Datos'!G32-'1 · Datos'!G50 | H18: ='1 · Datos'!H11-'1 · Datos'!H32-'1 · Datos'!H50 | I18: ='1 · Datos'!I11-'1 · Datos'!I32-'1 · Datos'!I50 | J18: ='1 · Datos'!J11-'1 · Datos'!J32-'1 · Datos'!J50 | K18: ='1 · Datos'!K11-'1 · Datos'!K32-'1 · Datos'!K50 | ... O18: ='1 · Datos'!O11-'1 · Datos'!O32-'1 · Datos'!O50 | P18: =IF(N(INDEX('1 · Datos'!$D$11:$O$11,'0 · Configuración'!$C$9))=0,"—",IFERROR(SUM(OFFSET(D18,0,0,1,'0 · Configuración'!$C$9)),"—"))
B19: Margen EBITDA | D19: =IFERROR(('1 · Datos'!D11-'1 · Datos'!D32-'1 · Datos'!D50)/'1 · Datos'!D11,0) | E19: =IFERROR(('1 · Datos'!E11-'1 · Datos'!E32-'1 · Datos'!E50)/'1 · Datos'!E11,0) | F19: =IFERROR(('1 · Datos'!F11-'1 · Datos'!F32-'1 · Datos'!F50)/'1 · Datos'!F11,0) | G19: =IFERROR(('1 · Datos'!G11-'1 · Datos'!G32-'1 · Datos'!G50)/'1 · Datos'!G11,0) | H19: =IFERROR(('1 · Datos'!H11-'1 · Datos'!H32-'1 · Datos'!H50)/'1 · Datos'!H11,0) | I19: =IFERROR(('1 · Datos'!I11-'1 · Datos'!I32-'1 · Datos'!I50)/'1 · Datos'!I11,0) | J19: =IFERROR(('1 · Datos'!J11-'1 · Datos'!J32-'1 · Datos'!J50)/'1 · Datos'!J11,0) | K19: =IFERROR(('1 · Datos'!K11-'1 · Datos'!K32-'1 · Datos'!K50)/'1 · Datos'!K11,0) | ... O19: =IFERROR(('1 · Datos'!O11-'1 · Datos'!O32-'1 · Datos'!O50)/'1 · Datos'!O11,0) | P19: =IF(N(INDEX('1 · Datos'!$D$11:$O$11,'0 · Configuración'!$C$9))=0,"—",IFERROR((SUM(OFFSET('1 · Datos'!$D$11,0,0,1,'0 · Configuración'!$C$9))-SUM(OFFSET('1 · Datos'!$D$32,0,0,1,'0 · Configuración'!$C$9))-SUM(OFFSET('1 · Datos'!$D$50,0,0,1,'0 · Configuración'!$C$9)))/SUM(OFFSET('1 · Datos'!$D$11,0,0,1,'0 · Configuración'!$C$9)),"—"))

Sheet 5 · Gasto administrativo
B2: CONTROL DE GASTO ADMINISTRATIVO
B3: El gasto no se lee por su signo: se lee contra el presupuesto y contra el ingreso que lo sostiene.
B5: CONCEPTO | D5: Ene | E5: Feb | F5: Mar | G5: Abr | H5: May | I5: Jun | J5: Jul | K5: Ago | L5: Sep | M5: Oct | N5: Nov | O5: Dic | P5: AÑO
B6: GASTO REAL POR CATEGORÍA
B7: ='0 · Configuración'!C17 | D7: ='1 · Datos'!D44 | E7: ='1 · Datos'!E44 | F7: ='1 · Datos'!F44 | G7: ='1 · Datos'!G44 | H7: ='1 · Datos'!H44 | I7: ='1 · Datos'!I44 | J7: ='1 · Datos'!J44 | K7: ='1 · Datos'!K44 | ... O7: ='1 · Datos'!O44 | P7: =IF(N(INDEX('1 · Datos'!$D$11:$O$11,'0 · Configuración'!$C$9))=0,"—",IFERROR(SUM(OFFSET(D7,0,0,1,'0 · Configuración'!$C$9)),"—"))
B8: ='0 · Configuración'!C18 | D8: ='1 · Datos'!D45 | E8: ='1 · Datos'!E45 | F8: ='1 · Datos'!F45 | G8: ='1 · Datos'!G45 | H8: ='1 · Datos'!H45 | I8: ='1 · Datos'!I45 | J8: ='1 · Datos'!J45 | K8: ='1 · Datos'!K45 | ... O8: ='1 · Datos'!O45 | P8: =IF(N(INDEX('1 · Datos'!$D$11:$O$11,'0 · Configuración'!$C$9))=0,"—",IFERROR(SUM(OFFSET(D8,0,0,1,'0 · Configuración'!$C$9)),"—"))
B9: ='0 · Configuración'!C19 | D9: ='1 · Datos'!D46 | E9: ='1 · Datos'!E46 | F9: ='1 · Datos'!F46 | G9: ='1 · Datos'!G46 | H9: ='1 · Datos'!H46 | I9: ='1 · Datos'!I46 | J9: ='1 · Datos'!J46 | K9: ='1 · Datos'!K46 | ... O9: ='1 · Datos'!O46 | P9: =IF(N(INDEX('1 · Datos'!$D$11:$O$11,'0 · Configuración'!$C$9))=0,"—",IFERROR(SUM(OFFSET(D9,0,0,1,'0 · Configuración'!$C$9)),"—"))
B10: ='0 · Configuración'!C20 | D10: ='1 · Datos'!D47 | E10: ='1 · Datos'!E47 | F10: ='1 · Datos'!F47 | G10: ='1 · Datos'!G47 | H10: ='1 · Datos'!H47 | I10: ='1 · Datos'!I47 | J10: ='1 · Datos'!J47 | K10: ='1 · Datos'!K47 | ... O10: ='1 · Datos'!O47 | P10: =IF(N(INDEX('1 · Datos'!$D$11:$O$11,'0 · Configuración'!$C$9))=0,"—",IFERROR(SUM(OFFSET(D10,0,0,1,'0 · Configuración'!$C$9)),"—"))
B11: ='0 · Configuración'!C21 | D11: ='1 · Datos'!D48 | E11: ='1 · Datos'!E48 | F11: ='1 · Datos'!F48 | G11: ='1 · Datos'!G48 | H11: ='1 · Datos'!H48 | I11: ='1 · Datos'!I48 | J11: ='1 · Datos'!J48 | K11: ='1 · Datos'!K48 | ... O11: ='1 · Datos'!O48 | P11: =IF(N(INDEX('1 · Datos'!$D$11:$O$11,'0 · Configuración'!$C$9))=0,"—",IFERROR(SUM(OFFSET(D11,0,0,1,'0 · Configuración'!$C$9)),"—"))
B12: ='0 · Configuración'!C22 | D12: ='1 · Datos'!D49 | E12: ='1 · Datos'!E49 | F12: ='1 · Datos'!F49 | G12: ='1 · Datos'!G49 | H12: ='1 · Datos'!H49 | I12: ='1 · Datos'!I49 | J12: ='1 · Datos'!J49 | K12: ='1 · Datos'!K49 | ... O12: ='1 · Datos'!O49 | P12: =IF(N(INDEX('1 · Datos'!$D$11:$O$11,'0 · Configuración'!$C$9))=0,"—",IFERROR(SUM(OFFSET(D12,0,0,1,'0 · Configuración'!$C$9)),"—"))
B13: Total gasto administrativo | D13: ='1 · Datos'!D50 | E13: ='1 · Datos'!E50 | F13: ='1 · Datos'!F50 | G13: ='1 · Datos'!G50 | H13: ='1 · Datos'!H50 | I13: ='1 · Datos'!I50 | J13: ='1 · Datos'!J50 | K13: ='1 · Datos'!K50 | ... O13: ='1 · Datos'!O50 | P13: =IF(N(INDEX('1 · Datos'!$D$11:$O$11,'0 · Configuración'!$C$9))=0,"—",IFERROR(SUM(OFFSET(D13,0,0,1,'0 · Configuración'!$C$9)),"—"))
B14: CONTRA PRESUPUESTO
B15: Presupuesto | D15: ='1 · Datos'!D59 | E15: ='1 · Datos'!E59 | F15: ='1 · Datos'!F59 | G15: ='1 · Datos'!G59 | H15: ='1 · Datos'!H59 | I15: ='1 · Datos'!I59 | J15: ='1 · Datos'!J59 | K15: ='1 · Datos'!K59 | ... O15: ='1 · Datos'!O59 | P15: =IF(N(INDEX('1 · Datos'!$D$11:$O$11,'0 · Configuración'!$C$9))=0,"—",IFERROR(SUM(OFFSET(D15,0,0,1,'0 · Configuración'!$C$9)),"—"))
B16: Sobreejecución | D16: ='1 · Datos'!D50-'1 · Datos'!D59 | E16: ='1 · Datos'!E50-'1 · Datos'!E59 | F16: ='1 · Datos'!F50-'1 · Datos'!F59 | G16: ='1 · Datos'!G50-'1 · Datos'!G59 | H16: ='1 · Datos'!H50-'1 · Datos'!H59 | I16: ='1 · Datos'!I50-'1 · Datos'!I59 | J16: ='1 · Datos'!J50-'1 · Datos'!J59 | K16: ='1 · Datos'!K50-'1 · Datos'!K59 | ... O16: ='1 · Datos'!O50-'1 · Datos'!O59 | P16: =IF(N(INDEX('1 · Datos'!$D$11:$O$11,'0 · Configuración'!$C$9))=0,"—",IFERROR(SUM(OFFSET(D16,0,0,1,'0 · Configuración'!$C$9)),"—"))
B17: Ejecución | D17: =IFERROR('1 · Datos'!D50/'1 · Datos'!D59,0) | E17: =IFERROR('1 · Datos'!E50/'1 · Datos'!E59,0) | F17: =IFERROR('1 · Datos'!F50/'1 · Datos'!F59,0) | G17: =IFERROR('1 · Datos'!G50/'1 · Datos'!G59,0) | H17: =IFERROR('1 · Datos'!H50/'1 · Datos'!H59,0) | I17: =IFERROR('1 · Datos'!I50/'1 · Datos'!I59,0) | J17: =IFERROR('1 · Datos'!J50/'1 · Datos'!J59,0) | K17: =IFERROR('1 · Datos'!K50/'1 · Datos'!K59,0) | ... O17: =IFERROR('1 · Datos'!O50/'1 · Datos'!O59,0) | P17: =IF(N(INDEX('1 · Datos'!$D$11:$O$11,'0 · Configuración'!$C$9))=0,"—",IFERROR(AVERAGE(OFFSET(D17,0,0,1,'0 · Configuración'!$C$9)),"—"))
B18: PESO SOBRE INGRESO
B19: Gasto sobre ingreso | D19: =IFERROR('1 · Datos'!D50/'1 · Datos'!D11,0) | E19: =IFERROR('1 · Datos'!E50/'1 · Datos'!E11,0) | F19: =IFERROR('1 · Datos'!F50/'1 · Datos'!F11,0) | G19: =IFERROR('1 · Datos'!G50/'1 · Datos'!G11,0) | H19: =IFERROR('1 · Datos'!H50/'1 · Datos'!H11,0) | I19: =IFERROR('1 · Datos'!I50/'1 · Datos'!I11,0) | J19: =IFERROR('1 · Datos'!J50/'1 · Datos'!J11,0) | K19: =IFERROR('1 · Datos'!K50/'1 · Datos'!K11,0) | ... O19: =IFERROR('1 · Datos'!O50/'1 · Datos'!O11,0) | P19: =IF(N(INDEX('1 · Datos'!$D$11:$O$11,'0 · Configuración'!$C$9))=0,"—",IFERROR(AVERAGE(OFFSET(D19,0,0,1,'0 · Configuración'!$C$9)),"—"))

Sheet 6 · Caja, deuda y divisas
B2: PRONÓSTICO DE CAJA, DEUDA Y COBERTURAS
B3: Si hace falta inyección, aquí va — junto a la acción de deuda ya tomada, no solo el hueco.
B5: CONCEPTO | D5: Ene | E5: Feb | F5: Mar | G5: Abr | H5: May | I5: Jun | J5: Jul | K5: Ago | L5: Sep | M5: Oct | N5: Nov | O5: Dic | P5: AÑO
B6: FLUJO DE CAJA
B7: Recaudo de clientes | D7: ='1 · Datos'!D64 | E7: ='1 · Datos'!E64 | F7: ='1 · Datos'!F64 | G7: ='1 · Datos'!G64 | H7: ='1 · Datos'!H64 | I7: ='1 · Datos'!I64 | J7: ='1 · Datos'!J64 | K7: ='1 · Datos'!K64 | ... O7: ='1 · Datos'!O64 | P7: =IF(N(INDEX('1 · Datos'!$D$11:$O$11,'0 · Configuración'!$C$9))=0,"—",IFERROR(SUM(OFFSET(D7,0,0,1,'0 · Configuración'!$C$9)),"—"))
B8: Salidas operativas y de inversión | D8: =-('1 · Datos'!D65+'1 · Datos'!D66+'1 · Datos'!D67) | E8: =-('1 · Datos'!E65+'1 · Datos'!E66+'1 · Datos'!E67) | F8: =-('1 · Datos'!F65+'1 · Datos'!F66+'1 · Datos'!F67) | G8: =-('1 · Datos'!G65+'1 · Datos'!G66+'1 · Datos'!G67) | H8: =-('1 · Datos'!H65+'1 · Datos'!H66+'1 · Datos'!H67) | I8: =-('1 · Datos'!I65+'1 · Datos'!I66+'1 · Datos'!I67) | J8: =-('1 · Datos'!J65+'1 · Datos'!J66+'1 · Datos'!J67) | K8: =-('1 · Datos'!K65+'1 · Datos'!K66+'1 · Datos'!K67) | ... O8: =-('1 · Datos'!O65+'1 · Datos'!O66+'1 · Datos'!O67) | P8: =IF(N(INDEX('1 · Datos'!$D$11:$O$11,'0 · Configuración'!$C$9))=0,"—",IFERROR(SUM(OFFSET(D8,0,0,1,'0 · Configuración'!$C$9)),"—"))
B9: Deuda neta | D9: ='1 · Datos'!D69-'1 · Datos'!D68 | E9: ='1 · Datos'!E69-'1 · Datos'!E68 | F9: ='1 · Datos'!F69-'1 · Datos'!F68 | G9: ='1 · Datos'!G69-'1 · Datos'!G68 | H9: ='1 · Datos'!H69-'1 · Datos'!H68 | I9: ='1 · Datos'!I69-'1 · Datos'!I68 | J9: ='1 · Datos'!J69-'1 · Datos'!J68 | K9: ='1 · Datos'!K69-'1 · Datos'!K68 | ... O9: ='1 · Datos'!O69-'1 · Datos'!O68 | P9: =IF(N(INDEX('1 · Datos'!$D$11:$O$11,'0 · Configuración'!$C$9))=0,"—",IFERROR(SUM(OFFSET(D9,0,0,1,'0 · Configuración'!$C$9)),"—"))
B10: Flujo neto del mes | D10: ='1 · Datos'!D70 | E10: ='1 · Datos'!E70 | F10: ='1 · Datos'!F70 | G10: ='1 · Datos'!G70 | H10: ='1 · Datos'!H70 | I10: ='1 · Datos'!I70 | J10: ='1 · Datos'!J70 | K10: ='1 · Datos'!K70 | ... O10: ='1 · Datos'!O70 | P10: =IF(N(INDEX('1 · Datos'!$D$11:$O$11,'0 · Configuración'!$C$9))=0,"—",IFERROR(SUM(OFFSET(D10,0,0,1,'0 · Configuración'!$C$9)),"—"))
B11: Saldo de caja al cierre | D11: ='1 · Datos'!D71 | E11: ='1 · Datos'!E71 | F11: ='1 · Datos'!F71 | G11: ='1 · Datos'!G71 | H11: ='1 · Datos'!H71 | I11: ='1 · Datos'!I71 | J11: ='1 · Datos'!J71 | K11: ='1 · Datos'!K71 | ... O11: ='1 · Datos'!O71 | P11: =IF(N(INDEX('1 · Datos'!$D$11:$O$11,'0 · Configuración'!$C$9))=0,"—",IFERROR(INDEX(D11:O11,'0 · Configuración'!$C$9),"—"))
B12: Caja mínima de operación | D12: ='0 · Configuración'!$C$28 | E12: ='0 · Configuración'!$C$28 | F12: ='0 · Configuración'!$C$28 | G12: ='0 · Configuración'!$C$28 | H12: ='0 · Configuración'!$C$28 | I12: ='0 · Configuración'!$C$28 | J12: ='0 · Configuración'!$C$28 | K12: ='0 · Configuración'!$C$28 | ... O12: ='0 · Configuración'!$C$28
B13: Meses de caja | D13: =IFERROR('1 · Datos'!D71/'1 · Datos'!D65,0) | E13: =IFERROR('1 · Datos'!E71/'1 · Datos'!E65,0) | F13: =IFERROR('1 · Datos'!F71/'1 · Datos'!F65,0) | G13: =IFERROR('1 · Datos'!G71/'1 · Datos'!G65,0) | H13: =IFERROR('1 · Datos'!H71/'1 · Datos'!H65,0) | I13: =IFERROR('1 · Datos'!I71/'1 · Datos'!I65,0) | J13: =IFERROR('1 · Datos'!J71/'1 · Datos'!J65,0) | K13: =IFERROR('1 · Datos'!K71/'1 · Datos'!K65,0) | ... O13: =IFERROR('1 · Datos'!O71/'1 · Datos'!O65,0) | P13: =IF(N(INDEX('1 · Datos'!$D$11:$O$11,'0 · Configuración'!$C$9))=0,"—",IFERROR(AVERAGE(OFFSET(D13,0,0,1,'0 · Configuración'!$C$9)),"—"))
B14: DEUDA
B15: Saldo de deuda financiera | D15: ='1 · Datos'!D72 | E15: ='1 · Datos'!E72 | F15: ='1 · Datos'!F72 | G15: ='1 · Datos'!G72 | H15: ='1 · Datos'!H72 | I15: ='1 · Datos'!I72 | J15: ='1 · Datos'!J72 | K15: ='1 · Datos'!K72 | ... O15: ='1 · Datos'!O72 | P15: =IF(N(INDEX('1 · Datos'!$D$11:$O$11,'0 · Configuración'!$C$9))=0,"—",IFERROR(INDEX(D15:O15,'0 · Configuración'!$C$9),"—"))
B16: Deuda neta de caja | D16: ='1 · Datos'!D72-'1 · Datos'!D71 | E16: ='1 · Datos'!E72-'1 · Datos'!E71 | F16: ='1 · Datos'!F72-'1 · Datos'!F71 | G16: ='1 · Datos'!G72-'1 · Datos'!G71 | H16: ='1 · Datos'!H72-'1 · Datos'!H71 | I16: ='1 · Datos'!I72-'1 · Datos'!I71 | J16: ='1 · Datos'!J72-'1 · Datos'!J71 | K16: ='1 · Datos'!K72-'1 · Datos'!K71 | ... O16: ='1 · Datos'!O72-'1 · Datos'!O71 | P16: =IF(N(INDEX('1 · Datos'!$D$11:$O$11,'0 · Configuración'!$C$9))=0,"—",IFERROR(INDEX(D16:O16,'0 · Configuración'!$C$9),"—"))
B17: Apalancamiento (Deuda / EBITDA anualizado) | D17: =IFERROR('1 · Datos'!D72/((SUM('1 · Datos'!$D$11:D11)-SUM('1 · Datos'!$D$32:D32)-SUM('1 · Datos'!$D$50:D50))/(COLUMN()-3)*12),0) | E17: =IFERROR('1 · Datos'!E72/((SUM('1 · Datos'!$D$11:E11)-SUM('1 · Datos'!$D$32:E32)-SUM('1 · Datos'!$D$50:E50))/(COLUMN()-3)*12),0) | F17: =IFERROR('1 · Datos'!F72/((SUM('1 · Datos'!$D$11:F11)-SUM('1 · Datos'!$D$32:F32)-SUM('1 · Datos'!$D$50:F50))/(COLUMN()-3)*12),0) | G17: =IFERROR('1 · Datos'!G72/((SUM('1 · Datos'!$D$11:G11)-SUM('1 · Datos'!$D$32:G32)-SUM('1 · Datos'!$D$50:G50))/(COLUMN()-3)*12),0) | H17: =IFERROR('1 · Datos'!H72/((SUM('1 · Datos'!$D$11:H11)-SUM('1 · Datos'!$D$32:H32)-SUM('1 · Datos'!$D$50:H50))/(COLUMN()-3)*12),0) | I17: =IFERROR('1 · Datos'!I72/((SUM('1 · Datos'!$D$11:I11)-SUM('1 · Datos'!$D$32:I32)-SUM('1 · Datos'!$D$50:I50))/(COLUMN()-3)*12),0) | J17: =IFERROR('1 · Datos'!J72/((SUM('1 · Datos'!$D$11:J11)-SUM('1 · Datos'!$D$32:J32)-SUM('1 · Datos'!$D$50:J50))/(COLUMN()-3)*12),0) | K17: =IFERROR('1 · Datos'!K72/((SUM('1 · Datos'!$D$11:K11)-SUM('1 · Datos'!$D$32:K32)-SUM('1 · Datos'!$D$50:K50))/(COLUMN()-3)*12),0) | ... O17: =IFERROR('1 · Datos'!O72/((SUM('1 · Datos'!$D$11:O11)-SUM('1 · Datos'!$D$32:O32)-SUM('1 · Datos'!$D$50:O50))/(COLUMN()-3)*12),0) | P17: =IF(N(INDEX('1 · Datos'!$D$11:$O$11,'0 · Configuración'!$C$9))=0,"—",IFERROR(INDEX(D17:O17,'0 · Configuración'!$C$9),"—"))
B18: Máximo permitido | D18: ='0 · Configuración'!$C$29 | E18: ='0 · Configuración'!$C$29 | F18: ='0 · Configuración'!$C$29 | G18: ='0 · Configuración'!$C$29 | H18: ='0 · Configuración'!$C$29 | I18: ='0 · Configuración'!$C$29 | J18: ='0 · Configuración'!$C$29 | K18: ='0 · Configuración'!$C$29 | ... O18: ='0 · Configuración'!$C$29
B19: COBERTURA DE DIVISAS
B20: Exposición neta en USD | D20: ='1 · Datos'!D74 | E20: ='1 · Datos'!E74 | F20: ='1 · Datos'!F74 | G20: ='1 · Datos'!G74 | H20: ='1 · Datos'!H74 | I20: ='1 · Datos'!I74 | J20: ='1 · Datos'!J74 | K20: ='1 · Datos'!K74 | ... O20: ='1 · Datos'!O74 | P20: =IF(N(INDEX('1 · Datos'!$D$11:$O$11,'0 · Configuración'!$C$9))=0,"—",IFERROR(INDEX(D20:O20,'0 · Configuración'!$C$9),"—"))
B21: Cobertura contratada en USD | D21: ='1 · Datos'!D75 | E21: ='1 · Datos'!E75 | F21: ='1 · Datos'!F75 | G21: ='1 · Datos'!G75 | H21: ='1 · Datos'!H75 | I21: ='1 · Datos'!I75 | J21: ='1 · Datos'!J75 | K21: ='1 · Datos'!K75 | ... O21: ='1 · Datos'!O75 | P21: =IF(N(INDEX('1 · Datos'!$D$11:$O$11,'0 · Configuración'!$C$9))=0,"—",IFERROR(INDEX(D21:O21,'0 · Configuración'!$C$9),"—"))
B22: Porcentaje cubierto | D22: =IFERROR('1 · Datos'!D75/'1 · Datos'!D74,0) | E22: =IFERROR('1 · Datos'!E75/'1 · Datos'!E74,0) | F22: =IFERROR('1 · Datos'!F75/'1 · Datos'!F74,0) | G22: =IFERROR('1 · Datos'!G75/'1 · Datos'!G74,0) | H22: =IFERROR('1 · Datos'!H75/'1 · Datos'!H74,0) | I22: =IFERROR('1 · Datos'!I75/'1 · Datos'!I74,0) | J22: =IFERROR('1 · Datos'!J75/'1 · Datos'!J74,0) | K22: =IFERROR('1 · Datos'!K75/'1 · Datos'!K74,0) | ... O22: =IFERROR('1 · Datos'!O75/'1 · Datos'!O74,0) | P22: =IF(N(INDEX('1 · Datos'!$D$11:$O$11,'0 · Configuración'!$C$9))=0,"—",IFERROR(AVERAGE(OFFSET(D22,0,0,1,'0 · Configuración'!$C$9)),"—"))
B23: Exposición descubierta en moneda local | D23: =('1 · Datos'!D74-'1 · Datos'!D75)*'1 · Datos'!D73 | E23: =('1 · Datos'!E74-'1 · Datos'!E75)*'1 · Datos'!E73 | F23: =('1 · Datos'!F74-'1 · Datos'!F75)*'1 · Datos'!F73 | G23: =('1 · Datos'!G74-'1 · Datos'!G75)*'1 · Datos'!G73 | H23: =('1 · Datos'!H74-'1 · Datos'!H75)*'1 · Datos'!H73 | I23: =('1 · Datos'!I74-'1 · Datos'!I75)*'1 · Datos'!I73 | J23: =('1 · Datos'!J74-'1 · Datos'!J75)*'1 · Datos'!J73 | K23: =('1 · Datos'!K74-'1 · Datos'!K75)*'1 · Datos'!K73 | ... O23: =('1 · Datos'!O74-'1 · Datos'!O75)*'1 · Datos'!O73 | P23: =IF(N(INDEX('1 · Datos'!$D$11:$O$11,'0 · Configuración'!$C$9))=0,"—",IFERROR(INDEX(D23:O23,'0 · Configuración'!$C$9),"—"))
B24: TRM de cierre | D24: ='1 · Datos'!D73 | E24: ='1 · Datos'!E73 | F24: ='1 · Datos'!F73 | G24: ='1 · Datos'!G73 | H24: ='1 · Datos'!H73 | I24: ='1 · Datos'!I73 | J24: ='1 · Datos'!J73 | K24: ='1 · Datos'!K73 | ... O24: ='1 · Datos'!O73 | P24: =IF(N(INDEX('1 · Datos'!$D$11:$O$11,'0 · Configuración'!$C$9))=0,"—",IFERROR(INDEX(D24:O24,'0 · Configuración'!$C$9),"—"))

Sheet 7 · Cartera y proveedores
B2: CARTERA Y PAGOS A PROVEEDORES
B3: El cierre. Dos indicadores y la junta queda lista desde finanzas.
B5: CONCEPTO | D5: Ene | E5: Feb | F5: Mar | G5: Abr | H5: May | I5: Jun | J5: Jul | K5: Ago | L5: Sep | M5: Oct | N5: Nov | O5: Dic | P5: AÑO
B6: CARTERA
B7: Saldo de cartera | D7: ='1 · Datos'!D80 | E7: ='1 · Datos'!E80 | F7: ='1 · Datos'!F80 | G7: ='1 · Datos'!G80 | H7: ='1 · Datos'!H80 | I7: ='1 · Datos'!I80 | J7: ='1 · Datos'!J80 | K7: ='1 · Datos'!K80 | ... O7: ='1 · Datos'!O80 | P7: =IF(N(INDEX('1 · Datos'!$D$11:$O$11,'0 · Configuración'!$C$9))=0,"—",IFERROR(INDEX(D7:O7,'0 · Configuración'!$C$9),"—"))
B8: Días de cartera | D8: =IFERROR('1 · Datos'!D80/('1 · Datos'!D11/30),0) | E8: =IFERROR('1 · Datos'!E80/('1 · Datos'!E11/30),0) | F8: =IFERROR('1 · Datos'!F80/('1 · Datos'!F11/30),0) | G8: =IFERROR('1 · Datos'!G80/('1 · Datos'!G11/30),0) | H8: =IFERROR('1 · Datos'!H80/('1 · Datos'!H11/30),0) | I8: =IFERROR('1 · Datos'!I80/('1 · Datos'!I11/30),0) | J8: =IFERROR('1 · Datos'!J80/('1 · Datos'!J11/30),0) | K8: =IFERROR('1 · Datos'!K80/('1 · Datos'!K11/30),0) | ... O8: =IFERROR('1 · Datos'!O80/('1 · Datos'!O11/30),0) | P8: =IF(N(INDEX('1 · Datos'!$D$11:$O$11,'0 · Configuración'!$C$9))=0,"—",IFERROR(INDEX('1 · Datos'!$D$80:$O$80,'0 · Configuración'!$C$9)/(SUM(OFFSET('1 · Datos'!$D$11,0,0,1,'0 · Configuración'!$C$9))/'0 · Configuración'!$C$9/30),"—"))
B9: Objetivo | D9: ='0 · Configuración'!$C$30 | E9: ='0 · Configuración'!$C$30 | F9: ='0 · Configuración'!$C$30 | G9: ='0 · Configuración'!$C$30 | H9: ='0 · Configuración'!$C$30 | I9: ='0 · Configuración'!$C$30 | J9: ='0 · Configuración'!$C$30 | K9: ='0 · Configuración'!$C$30 | ... O9: ='0 · Configuración'!$C$30
B10: Cartera vencida > 60 días | D10: ='1 · Datos'!D81 | E10: ='1 · Datos'!E81 | F10: ='1 · Datos'!F81 | G10: ='1 · Datos'!G81 | H10: ='1 · Datos'!H81 | I10: ='1 · Datos'!I81 | J10: ='1 · Datos'!J81 | K10: ='1 · Datos'!K81 | ... O10: ='1 · Datos'!O81 | P10: =IF(N(INDEX('1 · Datos'!$D$11:$O$11,'0 · Configuración'!$C$9))=0,"—",IFERROR(INDEX(D10:O10,'0 · Configuración'!$C$9),"—"))
B11: Porcentaje vencido | D11: =IFERROR('1 · Datos'!D81/'1 · Datos'!D80,0) | E11: =IFERROR('1 · Datos'!E81/'1 · Datos'!E80,0) | F11: =IFERROR('1 · Datos'!F81/'1 · Datos'!F80,0) | G11: =IFERROR('1 · Datos'!G81/'1 · Datos'!G80,0) | H11: =IFERROR('1 · Datos'!H81/'1 · Datos'!H80,0) | I11: =IFERROR('1 · Datos'!I81/'1 · Datos'!I80,0) | J11: =IFERROR('1 · Datos'!J81/'1 · Datos'!J80,0) | K11: =IFERROR('1 · Datos'!K81/'1 · Datos'!K80,0) | ... O11: =IFERROR('1 · Datos'!O81/'1 · Datos'!O80,0) | P11: =IF(N(INDEX('1 · Datos'!$D$11:$O$11,'0 · Configuración'!$C$9))=0,"—",IFERROR(INDEX('1 · Datos'!$D$81:$O$81,'0 · Configuración'!$C$9)/INDEX('1 · Datos'!$D$80:$O$80,'0 · Configuración'!$C$9),"—"))
B12: PROVEEDORES
B13: Saldo de proveedores | D13: ='1 · Datos'!D82 | E13: ='1 · Datos'!E82 | F13: ='1 · Datos'!F82 | G13: ='1 · Datos'!G82 | H13: ='1 · Datos'!H82 | I13: ='1 · Datos'!I82 | J13: ='1 · Datos'!J82 | K13: ='1 · Datos'!K82 | ... O13: ='1 · Datos'!O82 | P13: =IF(N(INDEX('1 · Datos'!$D$11:$O$11,'0 · Configuración'!$C$9))=0,"—",IFERROR(INDEX(D13:O13,'0 · Configuración'!$C$9),"—"))
B14: Días de proveedores | D14: =IFERROR('1 · Datos'!D82/('1 · Datos'!D83/30),0) | E14: =IFERROR('1 · Datos'!E82/('1 · Datos'!E83/30),0) | F14: =IFERROR('1 · Datos'!F82/('1 · Datos'!F83/30),0) | G14: =IFERROR('1 · Datos'!G82/('1 · Datos'!G83/30),0) | H14: =IFERROR('1 · Datos'!H82/('1 · Datos'!H83/30),0) | I14: =IFERROR('1 · Datos'!I82/('1 · Datos'!I83/30),0) | J14: =IFERROR('1 · Datos'!J82/('1 · Datos'!J83/30),0) | K14: =IFERROR('1 · Datos'!K82/('1 · Datos'!K83/30),0) | ... O14: =IFERROR('1 · Datos'!O82/('1 · Datos'!O83/30),0) | P14: =IF(N(INDEX('1 · Datos'!$D$11:$O$11,'0 · Configuración'!$C$9))=0,"—",IFERROR(INDEX('1 · Datos'!$D$82:$O$82,'0 · Configuración'!$C$9)/(SUM(OFFSET('1 · Datos'!$D$83,0,0,1,'0 · Configuración'!$C$9))/'0 · Configuración'!$C$9/30),"—"))
B15: CICLO
B16: Ciclo de conversión (cartera − proveedores) | D16: =IFERROR('1 · Datos'!D80/('1 · Datos'!D11/30)-'1 · Datos'!D82/('1 · Datos'!D83/30),0) | E16: =IFERROR('1 · Datos'!E80/('1 · Datos'!E11/30)-'1 · Datos'!E82/('1 · Datos'!E83/30),0) | F16: =IFERROR('1 · Datos'!F80/('1 · Datos'!F11/30)-'1 · Datos'!F82/('1 · Datos'!F83/30),0) | G16: =IFERROR('1 · Datos'!G80/('1 · Datos'!G11/30)-'1 · Datos'!G82/('1 · Datos'!G83/30),0) | H16: =IFERROR('1 · Datos'!H80/('1 · Datos'!H11/30)-'1 · Datos'!H82/('1 · Datos'!H83/30),0) | I16: =IFERROR('1 · Datos'!I80/('1 · Datos'!I11/30)-'1 · Datos'!I82/('1 · Datos'!I83/30),0) | J16: =IFERROR('1 · Datos'!J80/('1 · Datos'!J11/30)-'1 · Datos'!J82/('1 · Datos'!J83/30),0) | K16: =IFERROR('1 · Datos'!K80/('1 · Datos'!K11/30)-'1 · Datos'!K82/('1 · Datos'!K83/30),0) | ... O16: =IFERROR('1 · Datos'!O80/('1 · Datos'!O11/30)-'1 · Datos'!O82/('1 · Datos'!O83/30),0) | P16: =IF(N(INDEX('1 · Datos'!$D$11:$O$11,'0 · Configuración'!$C$9))=0,"—",IFERROR(AVERAGE(OFFSET(D16,0,0,1,'0 · Configuración'!$C$9)),"—"))

Sheet 8 · Acciones
B2: ACCIONES Y DECISIONES
B3: Esta hoja no tiene fórmulas a propósito. Es la que convierte una mala cifra en una cifra con dueño.
B5: Una junta no pide que nada salga mal. Pide que haya acciones. Si un bloque del resumen dice «requiere acción» y no tiene fila aquí, la presentación no está lista.
B10: BLOQUE | C10: QUÉ PASÓ | D10: ACCIÓN YA TOMADA | E10: RESPONSABLE | F10: FECHA | G10: ESTADO
B11: 3 · Gasto administrativo | C11: Honorarios cerró 18% sobre presupuesto por dos asesorías no previstas. | D11: Se cerró el cupo de asesorías del último trimestre y toda contratación nueva pasa por comité. | E11: [NOMBRE] | F11: [FECHA] | G11: En curso
B12: 7 · Cartera | C12: La cartera vencida a más de 60 días pasó de 11% a 19% del saldo. | D12: Se frenó despacho a los tres clientes de mayor mora y se pactó plan de pago con el mayor. | E12: [NOMBRE] | F12: [FECHA] | G12: En curso

Sheet 9 · Preguntas de la junta
B2: LAS PREGUNTAS QUE VAN A HACER
B3: Se llena antes de la junta, no después. Es el bloque que evita que la reunión sea un interrogatorio.
B5: Parte de la preparación está en evaluar las posibles preguntas que van a realizar, que en últimas serían las que yo haría a un equipo que me presenta números e indicadores. Si están cubiertas de antemano, la junta deja de interrogar y empieza a aportar.
B10: CONOCE AL AUDITORIO
B11: Cada miembro de junta llega con un dolor distinto según de dónde viene. Anota el suyo y verás que la mitad de las preguntas se predicen solas.
B13: MIEMBRO DE JUNTA | C13: DE DÓNDE VIENE | D13: QUÉ LE DUELE
B21: PREGUNTAS ANTICIPADAS
B23: PREGUNTA QUE YO HARÍA SI ESTUVIERA DEL OTRO LADO | C23: RESPUESTA PREPARADA | D23: DÓNDE ESTÁ EL DATO
B24: ¿Por qué el margen de esa línea cayó dos meses seguidos? | D24: Hoja 4
B25: ¿El pipeline está validado con comercial o lo armó finanzas sola? | D25: Hoja 3
B26: ¿Cuántos meses de caja quedan si el recaudo cae 15%? | D26: Hoja 6
B27: ¿Qué parte de la exposición en dólares está descubierta hoy? | D27: Hoja 6
B28: ¿Quién es el dueño de cada acción de la hoja 8 y desde cuándo? | D28: Hoja 8
