Workbook
Name ccEtq: OFFSET(Calculos!$CZ$6,0,0,ccN,1)
Name ccLbl: OFFSET(Calculos!$AK$10,0,0,ccN,1)
Name ccN: MAX(1,COUNTA(Calculos!$AK$10:$AK$20))
Name ccP: OFFSET(Calculos!$DB$6,0,0,ccN,1)
Name ccPpto: OFFSET(Calculos!$AM$10,0,0,ccN,1)
Name ccR: OFFSET(Calculos!$DA$6,0,0,ccN,1)
Name ccReal: OFFSET(Calculos!$AL$10,0,0,ccN,1)
Name ccVar: OFFSET(Calculos!$DC$6,0,0,ccN,1)
Name cuentaLbl: OFFSET(Calculos!$F$7,0,0,cuentaN,1)
Name cuentaN: MAX(1,COUNTA(Calculos!$F$7:$F$47))
Name cuentaPpto: OFFSET(Calculos!$H$7,0,0,cuentaN,1)
Name cuentaReal: OFFSET(Calculos!$G$7,0,0,cuentaN,1)
Name linTabLbl: OFFSET(Calculos!$O$6,0,0,linTabN,1)
Name linTabN: MAX(1,COUNTA(Calculos!$O$6:$O$16))
Name pCorte: Seguimiento!$L$6
Name pIPC: 'PPTO 2027'!$G$7
Name pMesCorte: Seguimiento!$K$6
Name pMetaGastosIngresos: Calculos!$DI$8
Name pMetaMargenBruto: Calculos!$DI$5
Name pMetaMargenEbitda: Calculos!$DI$6
Name pMetaMargenNeto: Calculos!$DI$7
Name pSalario: 'PPTO 2027'!$G$8
Name pTasaRenta: 'PPTO 2027'!$G$59
Name rSegResumen: Seguimiento!$B$8:$F$21
Name SegmentaciónDeDatos_LíneaTab: #N/A

Sheet Guía
K7: 1 · PEGA TU REAL 2026
K8: Ve a la hoja PPTO 2027: es tu estado de resultados completo. Despliega los meses con el botón + del esquema; las celdas lila de Ene 26 a Dic 26 son tu real: reemplaza las cifras de ejemplo por las tuyas, cuenta por cuenta. Para agregar una cuenta, inserta una fila dentro de su bloque. Si el año no ha cerrado, usa real hasta el último cierre y un estimado para los meses que faltan. No incluyas el impuesto de renta: se calcula con la tasa de los supuestos.
K10: 2 · DEFINE LOS SUPUESTOS, EN LA MISMA HOJA
K11: Arriba solo hay dos supuestos generales: IPC y aumento salarial (las cuentas indexadas y la nómina los toman solas). El resto va implícito en la columna Crec. 2027 de cada cuenta: ventas (volumen × precio), costo de mercancía, deuda, una campaña o un recorte. La tasa de renta está en la fila Impuesto de renta. El presupuesto de cada mes es el mismo mes del 2026 por su crecimiento: conserva la estacionalidad.
K13: 3 · SENSIBILIZA SIN SALIR DE LA HOJA
K14: Todo se recalcula al instante. A la derecha de cada cuenta, subtotal y margen ves la variación del año y de cada trimestre (en pesos y en %), con barras, la tendencia mes a mes y el peso sobre los ingresos. Verde = mejora, rojo = empeora: en ingresos y utilidades, subir es verde; en costos y gastos, subir es rojo.
K16: 4 · LEE EL TABLERO
K17: Las pestañas cambian la línea del P&G en la tarjeta y en el gráfico mes a mes. La cascada muestra qué bloque explica el salto de utilidad y el Estado de resultados completo aparece como imagen vinculada. Las tablas de cuentas y centros de costo son tablas dinámicas: se actualizan al abrir el archivo o con Datos > Actualizar todo.
K19: 5 · HAZLE SEGUIMIENTO AL AÑO
K20: En la hoja Seguimiento pega tu real 2027 mes a mes (hoy trae cifras sintéticas de ejemplo) y elige el mes de corte. Verás el acumulado real contra el presupuesto de ese mismo periodo, por cuenta y por bloque del P&G, con semáforo. El resumen también sale en el tablero.
K22: LÍNEAS QUE RECONOCE EL TABLERO
K23: Ingresos operacionales, Costo de ventas, Gastos de administración, Gastos de ventas, Gastos financieros, Otros ingresos no operacionales y Otros gastos no operacionales. Usa esos nombres exactos en la columna Línea. Los centros de costo son libres. Si agregas o quitas cuentas, hazlo igual en la tabla de Seguimiento.
... K29: Hecho por Mauricio Escobar · arquitecto de decisiones financieras. Empresa y datos de ejemplo, ficticios.

Sheet Tablero

Sheet PPTO 2027
B2: PRESUPUESTO 2027 · ESTADO DE RESULTADOS REAL 2026 Y PRESUPUESTO 2027
B3: Celdas lila = editables: real 2026 mes a mes y el crecimiento 2027 de cada cuenta. Ppto 2027 = mismo mes del 2026 × (1 + crecimiento). Todo se recalcula al instante. Millones de pesos · datos de ejemplo.
B4: ← Volver al tablero
B6: SUPUESTOS GENERALES 2027
B7: Inflación (IPC) 2027 | G7: 0.04 | I7: Aplica a arriendos, servicios, honorarios y gastos indexados.
B8: Aumento salarial 2027 | G8: 0.07 | I8: Aplica a toda la nómina.
B9: El resto del crecimiento (volumen, precio, costo unitario, deuda) va implícito en la columna Crec. 2027 de cada cuenta: cámbialo ahí para sensibilizar.
I11: REAL | V11: PPTO | AJ11: SENSIBILIZACIÓN · 2027 contra 2026
B12: Cuenta | C12: Línea | D12: Tipo | E12: Centro de costo | F12: Driver | G12: Crec. 2027 | I12: Ene 26 | J12: Feb 26 | K12: Mar 26 | L12: Abr 26 | M12: May 26 | N12: Jun 26 | O12: Jul 26 | P12: Ago 26 | Q12: Sep 26 | R12: Oct 26 | S12: Nov 26 | T12: Dic 26 | U12: 2026 | V12: Ene 27 | W12: Feb 27 | X12: Mar 27 | Y12: Abr 27 | Z12: May 27 | AA12: Jun 27 | AB12: Jul 27 | AC12: Ago 27 | AD12: Sep 27 | AE12: Oct 27 | AF12: Nov 27 | AG12: Dic 27 | AH12: 2027 | AJ12: Var $ | AK12: Var % | AL12: Var $ Q1 | AM12: Var $ Q2 | AN12: Var $ Q3 | AO12: Var $ Q4 | AP12: Var % Q1 | AQ12: Var % Q2 | AR12: Var % Q3 | AS12: Var % Q4 | AT12: Tendencia 2027 | AU12: Peso 2026 | AV12: Peso 2027 | AW12: Δ peso pp
B13: INGRESOS OPERACIONALES
B14: Venta de mercancía nacional | C14: Ingresos operacionales | D14: Ingreso | E14: Comercial | F14: Ventas | G14: 0.113 | I14: 640000000 | J14: 680000000 | K14: 760000000 | L14: 760000000 | M14: 800000000 | N14: 800000000 | O14: 800000000 | P14: 840000000 | Q14: 800000000 | R14: 840000000 | S14: 920000000 | T14: 960000000 | U14: =SUM(I14:T14) -> 9600000000 | V14: =I14*(1+$G14) -> 712320000 | W14: =J14*(1+$G14) -> 756840000 | X14: =K14*(1+$G14) -> 845880000 | Y14: =L14*(1+$G14) -> 845880000 | Z14: =M14*(1+$G14) -> 890400000 | AA14: =N14*(1+$G14) -> 890400000 | AB14: =O14*(1+$G14) -> 890400000 | AC14: =P14*(1+$G14) -> 934920000 | ... AG14: =T14*(1+$G14) -> 1068480000 | AH14: =SUM(V14:AG14) -> 10684800000 | AJ14: =AH14-U14 -> 1084800000 | AK14: =IFERROR(AJ14/ABS(U14),"") -> 0.113 | AL14: =SUM(V14:X14)-SUM(I14:K14) -> 235040000 | AM14: =SUM(Y14:AA14)-SUM(L14:N14) -> 266680000 | AN14: =SUM(AB14:AD14)-SUM(O14:Q14) -> 275720000 | AO14: =SUM(AE14:AG14)-SUM(R14:T14) -> 307360000 | AP14: =IFERROR(AL14/ABS(SUM(I14:K14)),"") -> 0.113 | AQ14: =IFERROR(AM14/ABS(SUM(L14:N14)),"") -> 0.113 | AR14: =IFERROR(AN14/ABS(SUM(O14:Q14)),"") -> 0.113 | AS14: =IFERROR(AO14/ABS(SUM(R14:T14)),"") -> 0.113 | AU14: =IFERROR(U14/$U$17,0) -> 0.8 | AV14: =IFERROR(AH14/$AH$17,0) -> 0.78239093 | AW14: =(AV14-AU14)*100 -> -1.7609068
B15: Ventas canal digital | C15: Ingresos operacionales | D15: Ingreso | E15: Comercial | F15: Ventas | G15: 0.28 | I15: 120000000 | J15: 127500000 | K15: 142500000 | L15: 142500000 | M15: 150000000 | N15: 150000000 | O15: 150000000 | P15: 157500000 | Q15: 150000000 | R15: 157500000 | S15: 172500000 | T15: 180000000 | U15: =SUM(I15:T15) -> 1800000000 | V15: =I15*(1+$G15) -> 153600000 | W15: =J15*(1+$G15) -> 163200000 | X15: =K15*(1+$G15) -> 182400000 | Y15: =L15*(1+$G15) -> 182400000 | Z15: =M15*(1+$G15) -> 192000000 | AA15: =N15*(1+$G15) -> 192000000 | AB15: =O15*(1+$G15) -> 192000000 | AC15: =P15*(1+$G15) -> 201600000 | ... AG15: =T15*(1+$G15) -> 230400000 | AH15: =SUM(V15:AG15) -> 2304000000 | AJ15: =AH15-U15 -> 504000000 | AK15: =IFERROR(AJ15/ABS(U15),"") -> 0.28 | AL15: =SUM(V15:X15)-SUM(I15:K15) -> 109200000 | AM15: =SUM(Y15:AA15)-SUM(L15:N15) -> 123900000 | AN15: =SUM(AB15:AD15)-SUM(O15:Q15) -> 128100000 | AO15: =SUM(AE15:AG15)-SUM(R15:T15) -> 142800000 | AP15: =IFERROR(AL15/ABS(SUM(I15:K15)),"") -> 0.28 | AQ15: =IFERROR(AM15/ABS(SUM(L15:N15)),"") -> 0.28 | AR15: =IFERROR(AN15/ABS(SUM(O15:Q15)),"") -> 0.28 | AS15: =IFERROR(AO15/ABS(SUM(R15:T15)),"") -> 0.28 | AU15: =IFERROR(U15/$U$17,0) -> 0.15 | AV15: =IFERROR(AH15/$AH$17,0) -> 0.16870963 | AW15: =(AV15-AU15)*100 -> 1.8709635
B16: Servicios de instalación | C16: Ingresos operacionales | D16: Ingreso | E16: Comercial | F16: Ventas | G16: 0.113 | I16: 40000000 | J16: 42500000 | K16: 47500000 | L16: 47500000 | M16: 50000000 | N16: 50000000 | O16: 50000000 | P16: 52500000 | Q16: 50000000 | R16: 52500000 | S16: 57500000 | T16: 60000000 | U16: =SUM(I16:T16) -> 600000000 | V16: =I16*(1+$G16) -> 44520000 | W16: =J16*(1+$G16) -> 47302500 | X16: =K16*(1+$G16) -> 52867500 | Y16: =L16*(1+$G16) -> 52867500 | Z16: =M16*(1+$G16) -> 55650000 | AA16: =N16*(1+$G16) -> 55650000 | AB16: =O16*(1+$G16) -> 55650000 | AC16: =P16*(1+$G16) -> 58432500 | ... AG16: =T16*(1+$G16) -> 66780000 | AH16: =SUM(V16:AG16) -> 667800000 | AJ16: =AH16-U16 -> 67800000 | AK16: =IFERROR(AJ16/ABS(U16),"") -> 0.113 | AL16: =SUM(V16:X16)-SUM(I16:K16) -> 14690000 | AM16: =SUM(Y16:AA16)-SUM(L16:N16) -> 16667500 | AN16: =SUM(AB16:AD16)-SUM(O16:Q16) -> 17232500 | AO16: =SUM(AE16:AG16)-SUM(R16:T16) -> 19210000 | AP16: =IFERROR(AL16/ABS(SUM(I16:K16)),"") -> 0.113 | AQ16: =IFERROR(AM16/ABS(SUM(L16:N16)),"") -> 0.113 | AR16: =IFERROR(AN16/ABS(SUM(O16:Q16)),"") -> 0.113 | AS16: =IFERROR(AO16/ABS(SUM(R16:T16)),"") -> 0.113 | AU16: =IFERROR(U16/$U$17,0) -> 0.05 | AV16: =IFERROR(AH16/$AH$17,0) -> 0.048899433 | AW16: =(AV16-AU16)*100 -> -0.11005668
B17: Total ingresos operacionales | D17: Ingreso | I17: =SUM(I14:I16) -> 800000000 | J17: =SUM(J14:J16) -> 850000000 | K17: =SUM(K14:K16) -> 950000000 | L17: =SUM(L14:L16) -> 950000000 | M17: =SUM(M14:M16) -> 1000000000 | N17: =SUM(N14:N16) -> 1000000000 | O17: =SUM(O14:O16) -> 1000000000 | P17: =SUM(P14:P16) -> 1050000000 | ... T17: =SUM(T14:T16) -> 1200000000 | U17: =SUM(I17:T17) -> 12000000000 | V17: =SUM(V14:V16) -> 910440000 | W17: =SUM(W14:W16) -> 967342500 | X17: =SUM(X14:X16) -> 1081147500 | Y17: =SUM(Y14:Y16) -> 1081147500 | Z17: =SUM(Z14:Z16) -> 1138050000 | AA17: =SUM(AA14:AA16) -> 1138050000 | AB17: =SUM(AB14:AB16) -> 1138050000 | AC17: =SUM(AC14:AC16) -> 1194952500 | ... AG17: =SUM(AG14:AG16) -> 1365660000 | AH17: =SUM(V17:AG17) -> 13656600000 | AJ17: =AH17-U17 -> 1656600000 | AK17: =IFERROR(AJ17/ABS(U17),"") -> 0.13805 | AL17: =SUM(V17:X17)-SUM(I17:K17) -> 358930000 | AM17: =SUM(Y17:AA17)-SUM(L17:N17) -> 407247500 | AN17: =SUM(AB17:AD17)-SUM(O17:Q17) -> 421052500 | AO17: =SUM(AE17:AG17)-SUM(R17:T17) -> 469370000 | AP17: =IFERROR(AL17/ABS(SUM(I17:K17)),"") -> 0.13805 | AQ17: =IFERROR(AM17/ABS(SUM(L17:N17)),"") -> 0.13805 | AR17: =IFERROR(AN17/ABS(SUM(O17:Q17)),"") -> 0.13805 | AS17: =IFERROR(AO17/ABS(SUM(R17:T17)),"") -> 0.13805 | AU17: =IFERROR(U17/$U$17,0) -> 1 | AV17: =IFERROR(AH17/$AH$17,0) -> 1 | AW17: =(AV17-AU17)*100 -> 0
B18: COSTO DE VENTAS
B19: Costo de mercancía vendida | C19: Costo de ventas | D19: Costo | E19: Operaciones | F19: Costo variable | G19: 0.1183 | I19: 466700000 | J19: 495800000 | K19: 554200000 | L19: 554200000 | M19: 583300000 | N19: 583300000 | O19: 583300000 | P19: 612500000 | Q19: 583300000 | R19: 612500000 | S19: 670800000 | T19: 700100000 | U19: =SUM(I19:T19) -> 7000000000 | V19: =I19*(1+$G19) -> 5.2191061e+08 | W19: =J19*(1+$G19) -> 554453140 | X19: =K19*(1+$G19) -> 619761860 | Y19: =L19*(1+$G19) -> 619761860 | Z19: =M19*(1+$G19) -> 652304390 | AA19: =N19*(1+$G19) -> 652304390 | AB19: =O19*(1+$G19) -> 652304390 | AC19: =P19*(1+$G19) -> 684958750 | ... AG19: =T19*(1+$G19) -> 782921830 | AH19: =SUM(V19:AG19) -> 7828100000 | AJ19: =AH19-U19 -> 828100000 | AK19: =IFERROR(AJ19/ABS(U19),"") -> 0.1183 | AL19: =SUM(V19:X19)-SUM(I19:K19) -> 179425610 | AM19: =SUM(Y19:AA19)-SUM(L19:N19) -> 203570640 | AN19: =SUM(AB19:AD19)-SUM(O19:Q19) -> 210467530 | AO19: =SUM(AE19:AG19)-SUM(R19:T19) -> 234636220 | AP19: =IFERROR(AL19/ABS(SUM(I19:K19)),"") -> 0.1183 | AQ19: =IFERROR(AM19/ABS(SUM(L19:N19)),"") -> 0.1183 | AR19: =IFERROR(AN19/ABS(SUM(O19:Q19)),"") -> 0.1183 | AS19: =IFERROR(AO19/ABS(SUM(R19:T19)),"") -> 0.1183 | AU19: =IFERROR(U19/$U$17,0) -> 0.58333333 | AV19: =IFERROR(AH19/$AH$17,0) -> 0.57321002 | AW19: =(AV19-AU19)*100 -> -1.012331
B20: Fletes de compra | C20: Costo de ventas | D20: Costo | E20: Operaciones | F20: Costo variable | G20: 0.1183 | I20: 32000000 | J20: 34000000 | K20: 38000000 | L20: 38000000 | M20: 40000000 | N20: 40000000 | O20: 40000000 | P20: 42000000 | Q20: 40000000 | R20: 42000000 | S20: 46000000 | T20: 48000000 | U20: =SUM(I20:T20) -> 480000000 | V20: =I20*(1+$G20) -> 35785600 | W20: =J20*(1+$G20) -> 38022200 | X20: =K20*(1+$G20) -> 42495400 | Y20: =L20*(1+$G20) -> 42495400 | Z20: =M20*(1+$G20) -> 44732000 | AA20: =N20*(1+$G20) -> 44732000 | AB20: =O20*(1+$G20) -> 44732000 | AC20: =P20*(1+$G20) -> 46968600 | ... AG20: =T20*(1+$G20) -> 53678400 | AH20: =SUM(V20:AG20) -> 536784000 | AJ20: =AH20-U20 -> 56784000 | AK20: =IFERROR(AJ20/ABS(U20),"") -> 0.1183 | AL20: =SUM(V20:X20)-SUM(I20:K20) -> 12303200 | AM20: =SUM(Y20:AA20)-SUM(L20:N20) -> 13959400 | AN20: =SUM(AB20:AD20)-SUM(O20:Q20) -> 14432600 | AO20: =SUM(AE20:AG20)-SUM(R20:T20) -> 16088800 | AP20: =IFERROR(AL20/ABS(SUM(I20:K20)),"") -> 0.1183 | AQ20: =IFERROR(AM20/ABS(SUM(L20:N20)),"") -> 0.1183 | AR20: =IFERROR(AN20/ABS(SUM(O20:Q20)),"") -> 0.1183 | AS20: =IFERROR(AO20/ABS(SUM(R20:T20)),"") -> 0.1183 | AU20: =IFERROR(U20/$U$17,0) -> 0.04 | AV20: =IFERROR(AH20/$AH$17,0) -> 0.03930583 | AW20: =(AV20-AU20)*100 -> -0.069416985
B21: Mermas y averías | C21: Costo de ventas | D21: Costo | E21: Operaciones | F21: Costo variable | G21: 0.1183 | I21: 10000000 | J21: 10600000 | K21: 11900000 | L21: 11900000 | M21: 12500000 | N21: 12500000 | O21: 12500000 | P21: 13100000 | Q21: 12500000 | R21: 13100000 | S21: 14400000 | T21: 15000000 | U21: =SUM(I21:T21) -> 150000000 | V21: =I21*(1+$G21) -> 11183000 | W21: =J21*(1+$G21) -> 11853980 | X21: =K21*(1+$G21) -> 13307770 | Y21: =L21*(1+$G21) -> 13307770 | Z21: =M21*(1+$G21) -> 13978750 | AA21: =N21*(1+$G21) -> 13978750 | AB21: =O21*(1+$G21) -> 13978750 | AC21: =P21*(1+$G21) -> 14649730 | ... AG21: =T21*(1+$G21) -> 16774500 | AH21: =SUM(V21:AG21) -> 167745000 | AJ21: =AH21-U21 -> 17745000 | AK21: =IFERROR(AJ21/ABS(U21),"") -> 0.1183 | AL21: =SUM(V21:X21)-SUM(I21:K21) -> 3844750 | AM21: =SUM(Y21:AA21)-SUM(L21:N21) -> 4365270 | AN21: =SUM(AB21:AD21)-SUM(O21:Q21) -> 4507230 | AO21: =SUM(AE21:AG21)-SUM(R21:T21) -> 5027750 | AP21: =IFERROR(AL21/ABS(SUM(I21:K21)),"") -> 0.1183 | AQ21: =IFERROR(AM21/ABS(SUM(L21:N21)),"") -> 0.1183 | AR21: =IFERROR(AN21/ABS(SUM(O21:Q21)),"") -> 0.1183 | AS21: =IFERROR(AO21/ABS(SUM(R21:T21)),"") -> 0.1183 | AU21: =IFERROR(U21/$U$17,0) -> 0.0125 | AV21: =IFERROR(AH21/$AH$17,0) -> 0.012283072 | AW21: =(AV21-AU21)*100 -> -0.021692808
B22: Total costo de ventas | D22: Costo | I22: =SUM(I19:I21) -> 508700000 | J22: =SUM(J19:J21) -> 540400000 | K22: =SUM(K19:K21) -> 604100000 | L22: =SUM(L19:L21) -> 604100000 | M22: =SUM(M19:M21) -> 635800000 | N22: =SUM(N19:N21) -> 635800000 | O22: =SUM(O19:O21) -> 635800000 | P22: =SUM(P19:P21) -> 667600000 | ... T22: =SUM(T19:T21) -> 763100000 | U22: =SUM(I22:T22) -> 7630000000 | V22: =SUM(V19:V21) -> 568879210 | W22: =SUM(W19:W21) -> 604329320 | X22: =SUM(X19:X21) -> 675565030 | Y22: =SUM(Y19:Y21) -> 675565030 | Z22: =SUM(Z19:Z21) -> 711015140 | AA22: =SUM(AA19:AA21) -> 711015140 | AB22: =SUM(AB19:AB21) -> 711015140 | AC22: =SUM(AC19:AC21) -> 746577080 | ... AG22: =SUM(AG19:AG21) -> 853374730 | AH22: =SUM(V22:AG22) -> 8532629000 | AJ22: =AH22-U22 -> 902629000 | AK22: =IFERROR(AJ22/ABS(U22),"") -> 0.1183 | AL22: =SUM(V22:X22)-SUM(I22:K22) -> 195573560 | AM22: =SUM(Y22:AA22)-SUM(L22:N22) -> 221895310 | AN22: =SUM(AB22:AD22)-SUM(O22:Q22) -> 229407360 | AO22: =SUM(AE22:AG22)-SUM(R22:T22) -> 255752770 | AP22: =IFERROR(AL22/ABS(SUM(I22:K22)),"") -> 0.1183 | AQ22: =IFERROR(AM22/ABS(SUM(L22:N22)),"") -> 0.1183 | AR22: =IFERROR(AN22/ABS(SUM(O22:Q22)),"") -> 0.1183 | AS22: =IFERROR(AO22/ABS(SUM(R22:T22)),"") -> 0.1183 | AU22: =IFERROR(U22/$U$17,0) -> 0.63583333 | AV22: =IFERROR(AH22/$AH$17,0) -> 0.62479893 | AW22: =(AV22-AU22)*100 -> -1.1034408
B23: Utilidad bruta | D23: T | I23: =I17-I22 -> 291300000 | J23: =J17-J22 -> 309600000 | K23: =K17-K22 -> 345900000 | L23: =L17-L22 -> 345900000 | M23: =M17-M22 -> 364200000 | N23: =N17-N22 -> 364200000 | O23: =O17-O22 -> 364200000 | P23: =P17-P22 -> 382400000 | ... T23: =T17-T22 -> 436900000 | U23: =SUM(I23:T23) -> 4370000000 | V23: =V17-V22 -> 341560790 | W23: =W17-W22 -> 363013180 | X23: =X17-X22 -> 405582470 | Y23: =Y17-Y22 -> 405582470 | Z23: =Z17-Z22 -> 427034860 | AA23: =AA17-AA22 -> 427034860 | AB23: =AB17-AB22 -> 427034860 | AC23: =AC17-AC22 -> 448375420 | ... AG23: =AG17-AG22 -> 512285270 | AH23: =SUM(V23:AG23) -> 5123971000 | AJ23: =AH23-U23 -> 753971000 | AK23: =IFERROR(AJ23/ABS(U23),"") -> 0.17253341 | AL23: =SUM(V23:X23)-SUM(I23:K23) -> 163356440 | AM23: =SUM(Y23:AA23)-SUM(L23:N23) -> 185352190 | AN23: =SUM(AB23:AD23)-SUM(O23:Q23) -> 191645140 | AO23: =SUM(AE23:AG23)-SUM(R23:T23) -> 213617230 | AP23: =IFERROR(AL23/ABS(SUM(I23:K23)),"") -> 0.17253532 | AQ23: =IFERROR(AM23/ABS(SUM(L23:N23)),"") -> 0.17253299 | AR23: =IFERROR(AN23/ABS(SUM(O23:Q23)),"") -> 0.17252893 | AS23: =IFERROR(AO23/ABS(SUM(R23:T23)),"") -> 0.17253633 | AU23: =IFERROR(U23/$U$17,0) -> 0.36416667 | AV23: =IFERROR(AH23/$AH$17,0) -> 0.37520107 | AW23: =(AV23-AU23)*100 -> 1.1034408
B24: Margen bruto | D24: M | I24: =IFERROR(I23/I17,0) -> 0.364125 | J24: =IFERROR(J23/J17,0) -> 0.36423529 | K24: =IFERROR(K23/K17,0) -> 0.36410526 | L24: =IFERROR(L23/L17,0) -> 0.36410526 | M24: =IFERROR(M23/M17,0) -> 0.3642 | N24: =IFERROR(N23/N17,0) -> 0.3642 | O24: =IFERROR(O23/O17,0) -> 0.3642 | P24: =IFERROR(P23/P17,0) -> 0.36419048 | ... AH24: =IFERROR(AH23/AH17,0) -> 0.37520107 | AK24: =(AH24-U24)*100 -> 1.1034408 | AP24: =(IFERROR(SUM(V23:X23)/SUM(V17:X17),0)-IFERROR(SUM(I23:K23)/SUM(I17:K17),0))*100 -> 1.1034631 | AQ24: =(IFERROR(SUM(Y23:AA23)/SUM(Y17:AA17),0)-IFERROR(SUM(L23:N23)/SUM(L17:N17),0))*100 -> 1.1034359 | AR24: =(IFERROR(SUM(AB23:AD23)/SUM(AB17:AD17),0)-IFERROR(SUM(O23:Q23)/SUM(O17:Q17),0))*100 -> 1.1033887 | AS24: =(IFERROR(SUM(AE23:AG23)/SUM(AE17:AG17),0)-IFERROR(SUM(R23:T23)/SUM(R17:T17),0))*100 -> 1.1034749
B26: GASTOS DE ADMINISTRACIÓN
B27: Nómina administrativa | C27: Gastos de administración | D27: Gasto | E27: Administración | F27: Nómina | G27: =pSalario -> 0.07 | I27: 50000000 | J27: 50000000 | K27: 50000000 | L27: 50000000 | M27: 50000000 | N27: 50000000 | O27: 50000000 | P27: 50000000 | Q27: 50000000 | R27: 50000000 | S27: 50000000 | T27: 50000000 | U27: =SUM(I27:T27) -> 600000000 | V27: =I27*(1+$G27) -> 53500000 | W27: =J27*(1+$G27) -> 53500000 | X27: =K27*(1+$G27) -> 53500000 | Y27: =L27*(1+$G27) -> 53500000 | Z27: =M27*(1+$G27) -> 53500000 | AA27: =N27*(1+$G27) -> 53500000 | AB27: =O27*(1+$G27) -> 53500000 | AC27: =P27*(1+$G27) -> 53500000 | ... AG27: =T27*(1+$G27) -> 53500000 | AH27: =SUM(V27:AG27) -> 642000000 | AJ27: =AH27-U27 -> 42000000 | AK27: =IFERROR(AJ27/ABS(U27),"") -> 0.07 | AL27: =SUM(V27:X27)-SUM(I27:K27) -> 10500000 | AM27: =SUM(Y27:AA27)-SUM(L27:N27) -> 10500000 | AN27: =SUM(AB27:AD27)-SUM(O27:Q27) -> 10500000 | AO27: =SUM(AE27:AG27)-SUM(R27:T27) -> 10500000 | AP27: =IFERROR(AL27/ABS(SUM(I27:K27)),"") -> 0.07 | AQ27: =IFERROR(AM27/ABS(SUM(L27:N27)),"") -> 0.07 | AR27: =IFERROR(AN27/ABS(SUM(O27:Q27)),"") -> 0.07 | AS27: =IFERROR(AO27/ABS(SUM(R27:T27)),"") -> 0.07 | AU27: =IFERROR(U27/$U$17,0) -> 0.05 | AV27: =IFERROR(AH27/$AH$17,0) -> 0.047010237 | AW27: =(AV27-AU27)*100 -> -0.29897632
B28: Arrendamiento de oficinas | C28: Gastos de administración | D28: Gasto | E28: Administración | F28: IPC | G28: =pIPC -> 0.04 | I28: 15000000 | J28: 15000000 | K28: 15000000 | L28: 15000000 | M28: 15000000 | N28: 15000000 | O28: 15000000 | P28: 15000000 | Q28: 15000000 | R28: 15000000 | S28: 15000000 | T28: 15000000 | U28: =SUM(I28:T28) -> 180000000 | V28: =I28*(1+$G28) -> 15600000 | W28: =J28*(1+$G28) -> 15600000 | X28: =K28*(1+$G28) -> 15600000 | Y28: =L28*(1+$G28) -> 15600000 | Z28: =M28*(1+$G28) -> 15600000 | AA28: =N28*(1+$G28) -> 15600000 | AB28: =O28*(1+$G28) -> 15600000 | AC28: =P28*(1+$G28) -> 15600000 | ... AG28: =T28*(1+$G28) -> 15600000 | AH28: =SUM(V28:AG28) -> 187200000 | AJ28: =AH28-U28 -> 7200000 | AK28: =IFERROR(AJ28/ABS(U28),"") -> 0.04 | AL28: =SUM(V28:X28)-SUM(I28:K28) -> 1800000 | AM28: =SUM(Y28:AA28)-SUM(L28:N28) -> 1800000 | AN28: =SUM(AB28:AD28)-SUM(O28:Q28) -> 1800000 | AO28: =SUM(AE28:AG28)-SUM(R28:T28) -> 1800000 | AP28: =IFERROR(AL28/ABS(SUM(I28:K28)),"") -> 0.04 | AQ28: =IFERROR(AM28/ABS(SUM(L28:N28)),"") -> 0.04 | AR28: =IFERROR(AN28/ABS(SUM(O28:Q28)),"") -> 0.04 | AS28: =IFERROR(AO28/ABS(SUM(R28:T28)),"") -> 0.04 | AU28: =IFERROR(U28/$U$17,0) -> 0.015 | AV28: =IFERROR(AH28/$AH$17,0) -> 0.013707658 | AW28: =(AV28-AU28)*100 -> -0.12923422
B29: Servicios públicos | C29: Gastos de administración | D29: Gasto | E29: Administración | F29: IPC | G29: =pIPC -> 0.04 | I29: 7000000 | J29: 7000000 | K29: 7000000 | L29: 7000000 | M29: 7000000 | N29: 7000000 | O29: 7000000 | P29: 7000000 | Q29: 7000000 | R29: 7000000 | S29: 7000000 | T29: 7000000 | U29: =SUM(I29:T29) -> 84000000 | V29: =I29*(1+$G29) -> 7280000 | W29: =J29*(1+$G29) -> 7280000 | X29: =K29*(1+$G29) -> 7280000 | Y29: =L29*(1+$G29) -> 7280000 | Z29: =M29*(1+$G29) -> 7280000 | AA29: =N29*(1+$G29) -> 7280000 | AB29: =O29*(1+$G29) -> 7280000 | AC29: =P29*(1+$G29) -> 7280000 | ... AG29: =T29*(1+$G29) -> 7280000 | AH29: =SUM(V29:AG29) -> 87360000 | AJ29: =AH29-U29 -> 3360000 | AK29: =IFERROR(AJ29/ABS(U29),"") -> 0.04 | AL29: =SUM(V29:X29)-SUM(I29:K29) -> 840000 | AM29: =SUM(Y29:AA29)-SUM(L29:N29) -> 840000 | AN29: =SUM(AB29:AD29)-SUM(O29:Q29) -> 840000 | AO29: =SUM(AE29:AG29)-SUM(R29:T29) -> 840000 | AP29: =IFERROR(AL29/ABS(SUM(I29:K29)),"") -> 0.04 | AQ29: =IFERROR(AM29/ABS(SUM(L29:N29)),"") -> 0.04 | AR29: =IFERROR(AN29/ABS(SUM(O29:Q29)),"") -> 0.04 | AS29: =IFERROR(AO29/ABS(SUM(R29:T29)),"") -> 0.04 | AU29: =IFERROR(U29/$U$17,0) -> 0.007 | AV29: =IFERROR(AH29/$AH$17,0) -> 0.006396907 | AW29: =(AV29-AU29)*100 -> -0.060309301
B30: Honorarios profesionales | C30: Gastos de administración | D30: Gasto | E30: Administración | F30: IPC | G30: -0.22 | I30: 10000000 | J30: 10000000 | K30: 10000000 | L30: 10000000 | M30: 10000000 | N30: 10000000 | O30: 10000000 | P30: 10000000 | Q30: 10000000 | R30: 10000000 | S30: 10000000 | T30: 10000000 | U30: =SUM(I30:T30) -> 120000000 | V30: =I30*(1+$G30) -> 7800000 | W30: =J30*(1+$G30) -> 7800000 | X30: =K30*(1+$G30) -> 7800000 | Y30: =L30*(1+$G30) -> 7800000 | Z30: =M30*(1+$G30) -> 7800000 | AA30: =N30*(1+$G30) -> 7800000 | AB30: =O30*(1+$G30) -> 7800000 | AC30: =P30*(1+$G30) -> 7800000 | ... AG30: =T30*(1+$G30) -> 7800000 | AH30: =SUM(V30:AG30) -> 93600000 | AJ30: =AH30-U30 -> -26400000 | AK30: =IFERROR(AJ30/ABS(U30),"") -> -0.22 | AL30: =SUM(V30:X30)-SUM(I30:K30) -> -6600000 | AM30: =SUM(Y30:AA30)-SUM(L30:N30) -> -6600000 | AN30: =SUM(AB30:AD30)-SUM(O30:Q30) -> -6600000 | AO30: =SUM(AE30:AG30)-SUM(R30:T30) -> -6600000 | AP30: =IFERROR(AL30/ABS(SUM(I30:K30)),"") -> -0.22 | AQ30: =IFERROR(AM30/ABS(SUM(L30:N30)),"") -> -0.22 | AR30: =IFERROR(AN30/ABS(SUM(O30:Q30)),"") -> -0.22 | AS30: =IFERROR(AO30/ABS(SUM(R30:T30)),"") -> -0.22 | AU30: =IFERROR(U30/$U$17,0) -> 0.01 | AV30: =IFERROR(AH30/$AH$17,0) -> 0.0068538289 | AW30: =(AV30-AU30)*100 -> -0.31461711
B31: Tecnología y software | C31: Gastos de administración | D31: Gasto | E31: Administración | F31: IPC | G31: =pIPC -> 0.04 | I31: 8000000 | J31: 8000000 | K31: 8000000 | L31: 8000000 | M31: 8000000 | N31: 8000000 | O31: 8000000 | P31: 8000000 | Q31: 8000000 | R31: 8000000 | S31: 8000000 | T31: 8000000 | U31: =SUM(I31:T31) -> 96000000 | V31: =I31*(1+$G31) -> 8320000 | W31: =J31*(1+$G31) -> 8320000 | X31: =K31*(1+$G31) -> 8320000 | Y31: =L31*(1+$G31) -> 8320000 | Z31: =M31*(1+$G31) -> 8320000 | AA31: =N31*(1+$G31) -> 8320000 | AB31: =O31*(1+$G31) -> 8320000 | AC31: =P31*(1+$G31) -> 8320000 | ... AG31: =T31*(1+$G31) -> 8320000 | AH31: =SUM(V31:AG31) -> 99840000 | AJ31: =AH31-U31 -> 3840000 | AK31: =IFERROR(AJ31/ABS(U31),"") -> 0.04 | AL31: =SUM(V31:X31)-SUM(I31:K31) -> 960000 | AM31: =SUM(Y31:AA31)-SUM(L31:N31) -> 960000 | AN31: =SUM(AB31:AD31)-SUM(O31:Q31) -> 960000 | AO31: =SUM(AE31:AG31)-SUM(R31:T31) -> 960000 | AP31: =IFERROR(AL31/ABS(SUM(I31:K31)),"") -> 0.04 | AQ31: =IFERROR(AM31/ABS(SUM(L31:N31)),"") -> 0.04 | AR31: =IFERROR(AN31/ABS(SUM(O31:Q31)),"") -> 0.04 | AS31: =IFERROR(AO31/ABS(SUM(R31:T31)),"") -> 0.04 | AU31: =IFERROR(U31/$U$17,0) -> 0.008 | AV31: =IFERROR(AH31/$AH$17,0) -> 0.0073107508 | AW31: =(AV31-AU31)*100 -> -0.068924915
B32: Depreciación y amortización | C32: Gastos de administración | D32: Gasto | E32: Administración | F32: Fijo | G32: 0 | I32: 15000000 | J32: 15000000 | K32: 15000000 | L32: 15000000 | M32: 15000000 | N32: 15000000 | O32: 15000000 | P32: 15000000 | Q32: 15000000 | R32: 15000000 | S32: 15000000 | T32: 15000000 | U32: =SUM(I32:T32) -> 180000000 | V32: =I32*(1+$G32) -> 15000000 | W32: =J32*(1+$G32) -> 15000000 | X32: =K32*(1+$G32) -> 15000000 | Y32: =L32*(1+$G32) -> 15000000 | Z32: =M32*(1+$G32) -> 15000000 | AA32: =N32*(1+$G32) -> 15000000 | AB32: =O32*(1+$G32) -> 15000000 | AC32: =P32*(1+$G32) -> 15000000 | ... AG32: =T32*(1+$G32) -> 15000000 | AH32: =SUM(V32:AG32) -> 180000000 | AJ32: =AH32-U32 -> 0 | AK32: =IFERROR(AJ32/ABS(U32),"") -> 0 | AL32: =SUM(V32:X32)-SUM(I32:K32) -> 0 | AM32: =SUM(Y32:AA32)-SUM(L32:N32) -> 0 | AN32: =SUM(AB32:AD32)-SUM(O32:Q32) -> 0 | AO32: =SUM(AE32:AG32)-SUM(R32:T32) -> 0 | AP32: =IFERROR(AL32/ABS(SUM(I32:K32)),"") -> 0 | AQ32: =IFERROR(AM32/ABS(SUM(L32:N32)),"") -> 0 | AR32: =IFERROR(AN32/ABS(SUM(O32:Q32)),"") -> 0 | AS32: =IFERROR(AO32/ABS(SUM(R32:T32)),"") -> 0 | AU32: =IFERROR(U32/$U$17,0) -> 0.015 | AV32: =IFERROR(AH32/$AH$17,0) -> 0.01318044 | AW32: =(AV32-AU32)*100 -> -0.18195598
B33: Total gastos de administración | D33: Gasto | I33: =SUM(I27:I32) -> 105000000 | J33: =SUM(J27:J32) -> 105000000 | K33: =SUM(K27:K32) -> 105000000 | L33: =SUM(L27:L32) -> 105000000 | M33: =SUM(M27:M32) -> 105000000 | N33: =SUM(N27:N32) -> 105000000 | O33: =SUM(O27:O32) -> 105000000 | P33: =SUM(P27:P32) -> 105000000 | ... T33: =SUM(T27:T32) -> 105000000 | U33: =SUM(I33:T33) -> 1260000000 | V33: =SUM(V27:V32) -> 107500000 | W33: =SUM(W27:W32) -> 107500000 | X33: =SUM(X27:X32) -> 107500000 | Y33: =SUM(Y27:Y32) -> 107500000 | Z33: =SUM(Z27:Z32) -> 107500000 | AA33: =SUM(AA27:AA32) -> 107500000 | AB33: =SUM(AB27:AB32) -> 107500000 | AC33: =SUM(AC27:AC32) -> 107500000 | ... AG33: =SUM(AG27:AG32) -> 107500000 | AH33: =SUM(V33:AG33) -> 1290000000 | AJ33: =AH33-U33 -> 30000000 | AK33: =IFERROR(AJ33/ABS(U33),"") -> 0.023809524 | AL33: =SUM(V33:X33)-SUM(I33:K33) -> 7500000 | AM33: =SUM(Y33:AA33)-SUM(L33:N33) -> 7500000 | AN33: =SUM(AB33:AD33)-SUM(O33:Q33) -> 7500000 | AO33: =SUM(AE33:AG33)-SUM(R33:T33) -> 7500000 | AP33: =IFERROR(AL33/ABS(SUM(I33:K33)),"") -> 0.023809524 | AQ33: =IFERROR(AM33/ABS(SUM(L33:N33)),"") -> 0.023809524 | AR33: =IFERROR(AN33/ABS(SUM(O33:Q33)),"") -> 0.023809524 | AS33: =IFERROR(AO33/ABS(SUM(R33:T33)),"") -> 0.023809524 | AU33: =IFERROR(U33/$U$17,0) -> 0.105 | AV33: =IFERROR(AH33/$AH$17,0) -> 0.094459822 | AW33: =(AV33-AU33)*100 -> -1.0540178
B34: GASTOS DE VENTAS
B35: Nómina comercial | C35: Gastos de ventas | D35: Gasto | E35: Comercial | F35: Nómina | G35: =pSalario -> 0.07 | I35: 43300000 | J35: 43300000 | K35: 43300000 | L35: 43300000 | M35: 43300000 | N35: 43300000 | O35: 43300000 | P35: 43300000 | Q35: 43300000 | R35: 43300000 | S35: 43300000 | T35: 43700000 | U35: =SUM(I35:T35) -> 520000000 | V35: =I35*(1+$G35) -> 46331000 | W35: =J35*(1+$G35) -> 46331000 | X35: =K35*(1+$G35) -> 46331000 | Y35: =L35*(1+$G35) -> 46331000 | Z35: =M35*(1+$G35) -> 46331000 | AA35: =N35*(1+$G35) -> 46331000 | AB35: =O35*(1+$G35) -> 46331000 | AC35: =P35*(1+$G35) -> 46331000 | ... AG35: =T35*(1+$G35) -> 46759000 | AH35: =SUM(V35:AG35) -> 556400000 | AJ35: =AH35-U35 -> 36400000 | AK35: =IFERROR(AJ35/ABS(U35),"") -> 0.07 | AL35: =SUM(V35:X35)-SUM(I35:K35) -> 9093000 | AM35: =SUM(Y35:AA35)-SUM(L35:N35) -> 9093000 | AN35: =SUM(AB35:AD35)-SUM(O35:Q35) -> 9093000 | AO35: =SUM(AE35:AG35)-SUM(R35:T35) -> 9121000 | AP35: =IFERROR(AL35/ABS(SUM(I35:K35)),"") -> 0.07 | AQ35: =IFERROR(AM35/ABS(SUM(L35:N35)),"") -> 0.07 | AR35: =IFERROR(AN35/ABS(SUM(O35:Q35)),"") -> 0.07 | AS35: =IFERROR(AO35/ABS(SUM(R35:T35)),"") -> 0.07 | AU35: =IFERROR(U35/$U$17,0) -> 0.043333333 | AV35: =IFERROR(AH35/$AH$17,0) -> 0.040742205 | AW35: =(AV35-AU35)*100 -> -0.25911281
B36: Comisiones de ventas | C36: Gastos de ventas | D36: Gasto | E36: Comercial | F36: Ventas | G36: 0.113 | I36: 24000000 | J36: 25500000 | K36: 28500000 | L36: 28500000 | M36: 30000000 | N36: 30000000 | O36: 30000000 | P36: 31500000 | Q36: 30000000 | R36: 31500000 | S36: 34500000 | T36: 36000000 | U36: =SUM(I36:T36) -> 360000000 | V36: =I36*(1+$G36) -> 26712000 | W36: =J36*(1+$G36) -> 28381500 | X36: =K36*(1+$G36) -> 31720500 | Y36: =L36*(1+$G36) -> 31720500 | Z36: =M36*(1+$G36) -> 33390000 | AA36: =N36*(1+$G36) -> 33390000 | AB36: =O36*(1+$G36) -> 33390000 | AC36: =P36*(1+$G36) -> 35059500 | ... AG36: =T36*(1+$G36) -> 40068000 | AH36: =SUM(V36:AG36) -> 400680000 | AJ36: =AH36-U36 -> 40680000 | AK36: =IFERROR(AJ36/ABS(U36),"") -> 0.113 | AL36: =SUM(V36:X36)-SUM(I36:K36) -> 8814000 | AM36: =SUM(Y36:AA36)-SUM(L36:N36) -> 10000500 | AN36: =SUM(AB36:AD36)-SUM(O36:Q36) -> 10339500 | AO36: =SUM(AE36:AG36)-SUM(R36:T36) -> 11526000 | AP36: =IFERROR(AL36/ABS(SUM(I36:K36)),"") -> 0.113 | AQ36: =IFERROR(AM36/ABS(SUM(L36:N36)),"") -> 0.113 | AR36: =IFERROR(AN36/ABS(SUM(O36:Q36)),"") -> 0.113 | AS36: =IFERROR(AO36/ABS(SUM(R36:T36)),"") -> 0.113 | AU36: =IFERROR(U36/$U$17,0) -> 0.03 | AV36: =IFERROR(AH36/$AH$17,0) -> 0.02933966 | AW36: =(AV36-AU36)*100 -> -0.066034006
B37: Publicidad y mercadeo | C37: Gastos de ventas | D37: Gasto | E37: Comercial | F37: IPC | G37: 0.352 | I37: 20000000 | J37: 20000000 | K37: 20000000 | L37: 20000000 | M37: 20000000 | N37: 20000000 | O37: 20000000 | P37: 20000000 | Q37: 20000000 | R37: 20000000 | S37: 20000000 | T37: 20000000 | U37: =SUM(I37:T37) -> 240000000 | V37: =I37*(1+$G37) -> 27040000 | W37: =J37*(1+$G37) -> 27040000 | X37: =K37*(1+$G37) -> 27040000 | Y37: =L37*(1+$G37) -> 27040000 | Z37: =M37*(1+$G37) -> 27040000 | AA37: =N37*(1+$G37) -> 27040000 | AB37: =O37*(1+$G37) -> 27040000 | AC37: =P37*(1+$G37) -> 27040000 | ... AG37: =T37*(1+$G37) -> 27040000 | AH37: =SUM(V37:AG37) -> 3.2448e+08 | AJ37: =AH37-U37 -> 84480000 | AK37: =IFERROR(AJ37/ABS(U37),"") -> 0.352 | AL37: =SUM(V37:X37)-SUM(I37:K37) -> 21120000 | AM37: =SUM(Y37:AA37)-SUM(L37:N37) -> 21120000 | AN37: =SUM(AB37:AD37)-SUM(O37:Q37) -> 21120000 | AO37: =SUM(AE37:AG37)-SUM(R37:T37) -> 21120000 | AP37: =IFERROR(AL37/ABS(SUM(I37:K37)),"") -> 0.352 | AQ37: =IFERROR(AM37/ABS(SUM(L37:N37)),"") -> 0.352 | AR37: =IFERROR(AN37/ABS(SUM(O37:Q37)),"") -> 0.352 | AS37: =IFERROR(AO37/ABS(SUM(R37:T37)),"") -> 0.352 | AU37: =IFERROR(U37/$U$17,0) -> 0.02 | AV37: =IFERROR(AH37/$AH$17,0) -> 0.02375994 | AW37: =(AV37-AU37)*100 -> 0.37599402
B38: Transporte y distribución | C38: Gastos de ventas | D38: Gasto | E38: Operaciones | F38: Volumen | G38: 0.06 | I38: 20000000 | J38: 21200000 | K38: 23800000 | L38: 23800000 | M38: 25000000 | N38: 25000000 | O38: 25000000 | P38: 26200000 | Q38: 25000000 | R38: 26200000 | S38: 28800000 | T38: 30000000 | U38: =SUM(I38:T38) -> 300000000 | V38: =I38*(1+$G38) -> 21200000 | W38: =J38*(1+$G38) -> 22472000 | X38: =K38*(1+$G38) -> 25228000 | Y38: =L38*(1+$G38) -> 25228000 | Z38: =M38*(1+$G38) -> 26500000 | AA38: =N38*(1+$G38) -> 26500000 | AB38: =O38*(1+$G38) -> 26500000 | AC38: =P38*(1+$G38) -> 27772000 | ... AG38: =T38*(1+$G38) -> 31800000 | AH38: =SUM(V38:AG38) -> 318000000 | AJ38: =AH38-U38 -> 18000000 | AK38: =IFERROR(AJ38/ABS(U38),"") -> 0.06 | AL38: =SUM(V38:X38)-SUM(I38:K38) -> 3900000 | AM38: =SUM(Y38:AA38)-SUM(L38:N38) -> 4428000 | AN38: =SUM(AB38:AD38)-SUM(O38:Q38) -> 4572000 | AO38: =SUM(AE38:AG38)-SUM(R38:T38) -> 5100000 | AP38: =IFERROR(AL38/ABS(SUM(I38:K38)),"") -> 0.06 | AQ38: =IFERROR(AM38/ABS(SUM(L38:N38)),"") -> 0.06 | AR38: =IFERROR(AN38/ABS(SUM(O38:Q38)),"") -> 0.06 | AS38: =IFERROR(AO38/ABS(SUM(R38:T38)),"") -> 0.06 | AU38: =IFERROR(U38/$U$17,0) -> 0.025 | AV38: =IFERROR(AH38/$AH$17,0) -> 0.023285444 | AW38: =(AV38-AU38)*100 -> -0.17145556
B39: Nómina de bodega | C39: Gastos de ventas | D39: Gasto | E39: Operaciones | F39: Nómina | G39: =pSalario -> 0.07 | I39: 31700000 | J39: 31700000 | K39: 31700000 | L39: 31700000 | M39: 31700000 | N39: 31700000 | O39: 31700000 | P39: 31700000 | Q39: 31700000 | R39: 31700000 | S39: 31700000 | T39: 31300000 | U39: =SUM(I39:T39) -> 380000000 | V39: =I39*(1+$G39) -> 33919000 | W39: =J39*(1+$G39) -> 33919000 | X39: =K39*(1+$G39) -> 33919000 | Y39: =L39*(1+$G39) -> 33919000 | Z39: =M39*(1+$G39) -> 33919000 | AA39: =N39*(1+$G39) -> 33919000 | AB39: =O39*(1+$G39) -> 33919000 | AC39: =P39*(1+$G39) -> 33919000 | ... AG39: =T39*(1+$G39) -> 33491000 | AH39: =SUM(V39:AG39) -> 406600000 | AJ39: =AH39-U39 -> 26600000 | AK39: =IFERROR(AJ39/ABS(U39),"") -> 0.07 | AL39: =SUM(V39:X39)-SUM(I39:K39) -> 6657000 | AM39: =SUM(Y39:AA39)-SUM(L39:N39) -> 6657000 | AN39: =SUM(AB39:AD39)-SUM(O39:Q39) -> 6657000 | AO39: =SUM(AE39:AG39)-SUM(R39:T39) -> 6629000 | AP39: =IFERROR(AL39/ABS(SUM(I39:K39)),"") -> 0.07 | AQ39: =IFERROR(AM39/ABS(SUM(L39:N39)),"") -> 0.07 | AR39: =IFERROR(AN39/ABS(SUM(O39:Q39)),"") -> 0.07 | AS39: =IFERROR(AO39/ABS(SUM(R39:T39)),"") -> 0.07 | AU39: =IFERROR(U39/$U$17,0) -> 0.031666667 | AV39: =IFERROR(AH39/$AH$17,0) -> 0.02977315 | AW39: =(AV39-AU39)*100 -> -0.18935167
B40: Arrendamiento de bodega | C40: Gastos de ventas | D40: Gasto | E40: Operaciones | F40: IPC | G40: =pIPC -> 0.04 | I40: 20000000 | J40: 20000000 | K40: 20000000 | L40: 20000000 | M40: 20000000 | N40: 20000000 | O40: 20000000 | P40: 20000000 | Q40: 20000000 | R40: 20000000 | S40: 20000000 | T40: 20000000 | U40: =SUM(I40:T40) -> 240000000 | V40: =I40*(1+$G40) -> 20800000 | W40: =J40*(1+$G40) -> 20800000 | X40: =K40*(1+$G40) -> 20800000 | Y40: =L40*(1+$G40) -> 20800000 | Z40: =M40*(1+$G40) -> 20800000 | AA40: =N40*(1+$G40) -> 20800000 | AB40: =O40*(1+$G40) -> 20800000 | AC40: =P40*(1+$G40) -> 20800000 | ... AG40: =T40*(1+$G40) -> 20800000 | AH40: =SUM(V40:AG40) -> 249600000 | AJ40: =AH40-U40 -> 9600000 | AK40: =IFERROR(AJ40/ABS(U40),"") -> 0.04 | AL40: =SUM(V40:X40)-SUM(I40:K40) -> 2400000 | AM40: =SUM(Y40:AA40)-SUM(L40:N40) -> 2400000 | AN40: =SUM(AB40:AD40)-SUM(O40:Q40) -> 2400000 | AO40: =SUM(AE40:AG40)-SUM(R40:T40) -> 2400000 | AP40: =IFERROR(AL40/ABS(SUM(I40:K40)),"") -> 0.04 | AQ40: =IFERROR(AM40/ABS(SUM(L40:N40)),"") -> 0.04 | AR40: =IFERROR(AN40/ABS(SUM(O40:Q40)),"") -> 0.04 | AS40: =IFERROR(AO40/ABS(SUM(R40:T40)),"") -> 0.04 | AU40: =IFERROR(U40/$U$17,0) -> 0.02 | AV40: =IFERROR(AH40/$AH$17,0) -> 0.018276877 | AW40: =(AV40-AU40)*100 -> -0.17231229
B41: Mantenimiento | C41: Gastos de ventas | D41: Gasto | E41: Operaciones | F41: IPC | G41: =pIPC -> 0.04 | I41: 7500000 | J41: 7500000 | K41: 7500000 | L41: 7500000 | M41: 7500000 | N41: 7500000 | O41: 7500000 | P41: 7500000 | Q41: 7500000 | R41: 7500000 | S41: 7500000 | T41: 7500000 | U41: =SUM(I41:T41) -> 90000000 | V41: =I41*(1+$G41) -> 7800000 | W41: =J41*(1+$G41) -> 7800000 | X41: =K41*(1+$G41) -> 7800000 | Y41: =L41*(1+$G41) -> 7800000 | Z41: =M41*(1+$G41) -> 7800000 | AA41: =N41*(1+$G41) -> 7800000 | AB41: =O41*(1+$G41) -> 7800000 | AC41: =P41*(1+$G41) -> 7800000 | ... AG41: =T41*(1+$G41) -> 7800000 | AH41: =SUM(V41:AG41) -> 93600000 | AJ41: =AH41-U41 -> 3600000 | AK41: =IFERROR(AJ41/ABS(U41),"") -> 0.04 | AL41: =SUM(V41:X41)-SUM(I41:K41) -> 900000 | AM41: =SUM(Y41:AA41)-SUM(L41:N41) -> 900000 | AN41: =SUM(AB41:AD41)-SUM(O41:Q41) -> 900000 | AO41: =SUM(AE41:AG41)-SUM(R41:T41) -> 900000 | AP41: =IFERROR(AL41/ABS(SUM(I41:K41)),"") -> 0.04 | AQ41: =IFERROR(AM41/ABS(SUM(L41:N41)),"") -> 0.04 | AR41: =IFERROR(AN41/ABS(SUM(O41:Q41)),"") -> 0.04 | AS41: =IFERROR(AO41/ABS(SUM(R41:T41)),"") -> 0.04 | AU41: =IFERROR(U41/$U$17,0) -> 0.0075 | AV41: =IFERROR(AH41/$AH$17,0) -> 0.0068538289 | AW41: =(AV41-AU41)*100 -> -0.064617108
B42: Total gastos de ventas | D42: Gasto | I42: =SUM(I35:I41) -> 166500000 | J42: =SUM(J35:J41) -> 169200000 | K42: =SUM(K35:K41) -> 174800000 | L42: =SUM(L35:L41) -> 174800000 | M42: =SUM(M35:M41) -> 177500000 | N42: =SUM(N35:N41) -> 177500000 | O42: =SUM(O35:O41) -> 177500000 | P42: =SUM(P35:P41) -> 180200000 | ... T42: =SUM(T35:T41) -> 188500000 | U42: =SUM(I42:T42) -> 2130000000 | V42: =SUM(V35:V41) -> 183802000 | W42: =SUM(W35:W41) -> 186743500 | X42: =SUM(X35:X41) -> 192838500 | Y42: =SUM(Y35:Y41) -> 192838500 | Z42: =SUM(Z35:Z41) -> 195780000 | AA42: =SUM(AA35:AA41) -> 195780000 | AB42: =SUM(AB35:AB41) -> 195780000 | AC42: =SUM(AC35:AC41) -> 198721500 | ... AG42: =SUM(AG35:AG41) -> 207758000 | AH42: =SUM(V42:AG42) -> 2349360000 | AJ42: =AH42-U42 -> 219360000 | AK42: =IFERROR(AJ42/ABS(U42),"") -> 0.10298592 | AL42: =SUM(V42:X42)-SUM(I42:K42) -> 52884000 | AM42: =SUM(Y42:AA42)-SUM(L42:N42) -> 54598500 | AN42: =SUM(AB42:AD42)-SUM(O42:Q42) -> 55081500 | AO42: =SUM(AE42:AG42)-SUM(R42:T42) -> 56796000 | AP42: =IFERROR(AL42/ABS(SUM(I42:K42)),"") -> 0.10359256 | AQ42: =IFERROR(AM42/ABS(SUM(L42:N42)),"") -> 0.10305493 | AR42: =IFERROR(AN42/ABS(SUM(O42:Q42)),"") -> 0.1029176 | AS42: =IFERROR(AO42/ABS(SUM(R42:T42)),"") -> 0.10242741 | AU42: =IFERROR(U42/$U$17,0) -> 0.1775 | AV42: =IFERROR(AH42/$AH$17,0) -> 0.17203111 | AW42: =(AV42-AU42)*100 -> -0.54688942
B43: Utilidad operacional (EBIT) | D43: T | I43: =I23-I33-I42 -> 19800000 | J43: =J23-J33-J42 -> 35400000 | K43: =K23-K33-K42 -> 66100000 | L43: =L23-L33-L42 -> 66100000 | M43: =M23-M33-M42 -> 81700000 | N43: =N23-N33-N42 -> 81700000 | O43: =O23-O33-O42 -> 81700000 | P43: =P23-P33-P42 -> 97200000 | ... T43: =T23-T33-T42 -> 143400000 | U43: =SUM(I43:T43) -> 980000000 | V43: =V23-V33-V42 -> 50258790 | W43: =W23-W33-W42 -> 68769680 | X43: =X23-X33-X42 -> 105243970 | Y43: =Y23-Y33-Y42 -> 105243970 | Z43: =Z23-Z33-Z42 -> 123754860 | AA43: =AA23-AA33-AA42 -> 123754860 | AB43: =AB23-AB33-AB42 -> 123754860 | AC43: =AC23-AC33-AC42 -> 142153920 | ... AG43: =AG23-AG33-AG42 -> 197027270 | AH43: =SUM(V43:AG43) -> 1484611000 | AJ43: =AH43-U43 -> 504611000 | AK43: =IFERROR(AJ43/ABS(U43),"") -> 0.51490918 | AL43: =SUM(V43:X43)-SUM(I43:K43) -> 102972440 | AM43: =SUM(Y43:AA43)-SUM(L43:N43) -> 123253690 | AN43: =SUM(AB43:AD43)-SUM(O43:Q43) -> 129063640 | AO43: =SUM(AE43:AG43)-SUM(R43:T43) -> 149321230 | AP43: =IFERROR(AL43/ABS(SUM(I43:K43)),"") -> 0.84890717 | AQ43: =IFERROR(AM43/ABS(SUM(L43:N43)),"") -> 0.53705312 | AR43: =IFERROR(AN43/ABS(SUM(O43:Q43)),"") -> 0.49525572 | AS43: =IFERROR(AO43/ABS(SUM(R43:T43)),"") -> 0.40510372 | AU43: =IFERROR(U43/$U$17,0) -> 0.081666667 | AV43: =IFERROR(AH43/$AH$17,0) -> 0.10871015 | AW43: =(AV43-AU43)*100 -> 2.7043481
B44: Margen operacional | D44: M | I44: =IFERROR(I43/I17,0) -> 0.02475 | J44: =IFERROR(J43/J17,0) -> 0.041647059 | K44: =IFERROR(K43/K17,0) -> 0.069578947 | L44: =IFERROR(L43/L17,0) -> 0.069578947 | M44: =IFERROR(M43/M17,0) -> 0.0817 | N44: =IFERROR(N43/N17,0) -> 0.0817 | O44: =IFERROR(O43/O17,0) -> 0.0817 | P44: =IFERROR(P43/P17,0) -> 0.092571429 | ... AH44: =IFERROR(AH43/AH17,0) -> 0.10871015 | AK44: =(AH44-U44)*100 -> 2.7043481 | AP44: =(IFERROR(SUM(V43:X43)/SUM(V17:X17),0)-IFERROR(SUM(I43:K43)/SUM(I17:K17),0))*100 -> 2.9141269 | AQ44: =(IFERROR(SUM(Y43:AA43)/SUM(Y17:AA17),0)-IFERROR(SUM(L43:N43)/SUM(L17:N17),0))*100 -> 2.7275682 | AR44: =(IFERROR(SUM(AB43:AD43)/SUM(AB17:AD17),0)-IFERROR(SUM(O43:Q43)/SUM(O17:Q17),0))*100 -> 2.6818324 | AS44: =(IFERROR(SUM(AE43:AG43)/SUM(AE17:AG17),0)-IFERROR(SUM(R43:T43)/SUM(R17:T17),0))*100 -> 2.54398
...

Sheet Estado de resultados
B2: ESTADO DE RESULTADOS · PRESUPUESTO 2027 VS. REAL 2026
B3: Millones de pesos · se recalcula al instante al cambiar un supuesto en la hoja PPTO 2027 · datos de ejemplo
B4: ← Volver al tablero
B6: Estado de resultados | C6: Real 2026 | D6: Ppto 2027 | E6: Var $ | F6: Var %
B7: Ingresos operacionales | C7: =(SUMIFS(qPPTO[Real],qPPTO[Línea],"Ingresos operacionales"))/1000000 -> 12000 | D7: =(SUMIFS(qPPTO[Presupuesto],qPPTO[Línea],"Ingresos operacionales"))/1000000 -> 13656.6 | E7: =D7-C7 -> 1656.6 | F7: =IFERROR(E7/ABS(C7),"") -> 0.13805
B8: Costo de ventas | C8: =(SUMIFS(qPPTO[Real],qPPTO[Línea],"Costo de ventas"))/1000000 -> 7630 | D8: =(SUMIFS(qPPTO[Presupuesto],qPPTO[Línea],"Costo de ventas"))/1000000 -> 8532.629 | E8: =D8-C8 -> 902.629 | F8: =IFERROR(E8/ABS(C8),"") -> 0.1183
B9: Utilidad bruta | C9: =(SUMIFS(qPPTO[Real],qPPTO[Línea],"Ingresos operacionales")-SUMIFS(qPPTO[Real],qPPTO[Línea],"Costo de ventas"))/1000000 -> 4370 | D9: =(SUMIFS(qPPTO[Presupuesto],qPPTO[Línea],"Ingresos operacionales")-SUMIFS(qPPTO[Presupuesto],qPPTO[Línea],"Costo de ventas"))/1000000 -> 5123.971 | E9: =D9-C9 -> 753.971 | F9: =IFERROR(E9/ABS(C9),"") -> 0.17253341
B10: Gastos de administración | C10: =(SUMIFS(qPPTO[Real],qPPTO[Línea],"Gastos de administración"))/1000000 -> 1260 | D10: =(SUMIFS(qPPTO[Presupuesto],qPPTO[Línea],"Gastos de administración"))/1000000 -> 1290 | E10: =D10-C10 -> 30 | F10: =IFERROR(E10/ABS(C10),"") -> 0.023809524
B11: Gastos de ventas | C11: =(SUMIFS(qPPTO[Real],qPPTO[Línea],"Gastos de ventas"))/1000000 -> 2130 | D11: =(SUMIFS(qPPTO[Presupuesto],qPPTO[Línea],"Gastos de ventas"))/1000000 -> 2349.36 | E11: =D11-C11 -> 219.36 | F11: =IFERROR(E11/ABS(C11),"") -> 0.10298592
B12: Utilidad operativa | C12: =(SUMIFS(qPPTO[Real],qPPTO[Línea],"Ingresos operacionales")-SUMIFS(qPPTO[Real],qPPTO[Línea],"Costo de ventas")-SUMIFS(qPPTO[Real],qPPTO[Línea],"Gastos de administración")-SUMIFS(qPPTO[Real],qPPTO[Línea],"Gastos de ventas"))/1000000 -> 980 | D12: =(SUMIFS(qPPTO[Presupuesto],qPPTO[Línea],"Ingresos operacionales")-SUMIFS(qPPTO[Presupuesto],qPPTO[Línea],"Costo de ventas")-SUMIFS(qPPTO[Presupuesto],qPPTO[Línea],"Gastos de administración")-SUMIFS(qPPTO[Presupuesto],qPPTO[Línea],"Gastos de ventas"))/1000000 -> 1484.611 | E12: =D12-C12 -> 504.611 | F12: =IFERROR(E12/ABS(C12),"") -> 0.51490918
B13: EBITDA | C13: =(SUMIFS(qPPTO[Real],qPPTO[Línea],"Ingresos operacionales")-SUMIFS(qPPTO[Real],qPPTO[Línea],"Costo de ventas")-SUMIFS(qPPTO[Real],qPPTO[Línea],"Gastos de administración")-SUMIFS(qPPTO[Real],qPPTO[Línea],"Gastos de ventas")+SUMIFS(qPPTO[Real],qPPTO[Cuenta],"Depreciación y amortización"))/1000000 -> 1160 | D13: =(SUMIFS(qPPTO[Presupuesto],qPPTO[Línea],"Ingresos operacionales")-SUMIFS(qPPTO[Presupuesto],qPPTO[Línea],"Costo de ventas")-SUMIFS(qPPTO[Presupuesto],qPPTO[Línea],"Gastos de administración")-SUMIFS(qPPTO[Presupuesto],qPPTO[Línea],"Gastos de ventas")+SUMIFS(qPPTO[Presupuesto],qPPTO[Cuenta],"Depreciación y amortización"))/1000000 -> 1664.611 | E13: =D13-C13 -> 504.611 | F13: =IFERROR(E13/ABS(C13),"") -> 0.43500948
B14: Gastos financieros | C14: =(SUMIFS(qPPTO[Real],qPPTO[Línea],"Gastos financieros"))/1000000 -> 308 | D14: =(SUMIFS(qPPTO[Presupuesto],qPPTO[Línea],"Gastos financieros"))/1000000 -> 283.92 | E14: =D14-C14 -> -24.08 | F14: =IFERROR(E14/ABS(C14),"") -> -0.078181818
B15: Otros ingresos no operacionales | C15: =(SUMIFS(qPPTO[Real],qPPTO[Línea],"Otros ingresos no operacionales"))/1000000 -> 60 | D15: =(SUMIFS(qPPTO[Presupuesto],qPPTO[Línea],"Otros ingresos no operacionales"))/1000000 -> 62.4 | E15: =D15-C15 -> 2.4 | F15: =IFERROR(E15/ABS(C15),"") -> 0.04
B16: Otros gastos no operacionales | C16: =(SUMIFS(qPPTO[Real],qPPTO[Línea],"Otros gastos no operacionales"))/1000000 -> 40 | D16: =(SUMIFS(qPPTO[Presupuesto],qPPTO[Línea],"Otros gastos no operacionales"))/1000000 -> 40 | E16: =D16-C16 -> 0 | F16: =IFERROR(E16/ABS(C16),"") -> 0
B17: Utilidad antes de impuestos | C17: =C12-C14+C15-C16 -> 692 | D17: =D12-D14+D15-D16 -> 1223.091 | E17: =D17-C17 -> 531.091 | F17: =IFERROR(E17/ABS(C17),"") -> 0.76747254
B18: Impuesto de renta | C18: =MAX(0,C17)*pTasaRenta -> 242.2 | D18: =MAX(0,D17)*pTasaRenta -> 428.08185 | E18: =D18-C18 -> 185.88185 | F18: =IFERROR(E18/ABS(C18),"") -> 0.76747254
B19: Utilidad neta | C19: =C17-C18 -> 449.8 | D19: =D17-D18 -> 795.00915 | E19: =D19-C19 -> 345.20915 | F19: =IFERROR(E19/ABS(C19),"") -> 0.76747254
B21: Márgenes | E21: Var
B22: Margen bruto | C22: =IFERROR(C9/C7,0) -> 0.36416667 | D22: =IFERROR(D9/D7,0) -> 0.37520107 | E22: =(D22-C22)*100 -> 1.1034408
B23: Margen EBITDA | C23: =IFERROR(C13/C7,0) -> 0.096666667 | D23: =IFERROR(D13/D7,0) -> 0.12189059 | E23: =(D23-C23)*100 -> 2.5223921
B24: Margen neto | C24: =IFERROR(C19/C7,0) -> 0.037483333 | D24: =IFERROR(D19/D7,0) -> 0.058214281 | E24: =(D24-C24)*100 -> 2.0730948
B27: MES A MES · PRESUPUESTO 2027 CONTRA EL MISMO MES DE 2026
B28: Variación de cada mes contra el mismo mes del año anterior, no contra el promedio. Tendencia: cómo se mueve esa variación a lo largo del año (verde el mes más alto, rojo el más bajo).
B30: Línea | C30: Real 2026 | D30: Ppto 2027 | E30: Var % | F30: Tendencia | H30: Ene | I30: Feb | J30: Mar | K30: Abr | L30: May | M30: Jun | N30: Jul | O30: Ago | P30: Sep | Q30: Oct | R30: Nov | S30: Dic
B31: Ingresos operacionales | C31: =C7 -> 12000 | D31: =D7 -> 13656.6 | E31: =F7 -> 0.13805 | H31: =IFERROR((SUMIFS(qPPTO[Presupuesto],qPPTO[Línea],"Ingresos operacionales",qPPTO[Mes],"Ene"))/(SUMIFS(qPPTO[Real],qPPTO[Línea],"Ingresos operacionales",qPPTO[Mes],"Ene"))-1,"") -> 0.13805 | I31: =IFERROR((SUMIFS(qPPTO[Presupuesto],qPPTO[Línea],"Ingresos operacionales",qPPTO[Mes],"Feb"))/(SUMIFS(qPPTO[Real],qPPTO[Línea],"Ingresos operacionales",qPPTO[Mes],"Feb"))-1,"") -> 0.13805 | J31: =IFERROR((SUMIFS(qPPTO[Presupuesto],qPPTO[Línea],"Ingresos operacionales",qPPTO[Mes],"Mar"))/(SUMIFS(qPPTO[Real],qPPTO[Línea],"Ingresos operacionales",qPPTO[Mes],"Mar"))-1,"") -> 0.13805 | K31: =IFERROR((SUMIFS(qPPTO[Presupuesto],qPPTO[Línea],"Ingresos operacionales",qPPTO[Mes],"Abr"))/(SUMIFS(qPPTO[Real],qPPTO[Línea],"Ingresos operacionales",qPPTO[Mes],"Abr"))-1,"") -> 0.13805 | L31: =IFERROR((SUMIFS(qPPTO[Presupuesto],qPPTO[Línea],"Ingresos operacionales",qPPTO[Mes],"May"))/(SUMIFS(qPPTO[Real],qPPTO[Línea],"Ingresos operacionales",qPPTO[Mes],"May"))-1,"") -> 0.13805 | M31: =IFERROR((SUMIFS(qPPTO[Presupuesto],qPPTO[Línea],"Ingresos operacionales",qPPTO[Mes],"Jun"))/(SUMIFS(qPPTO[Real],qPPTO[Línea],"Ingresos operacionales",qPPTO[Mes],"Jun"))-1,"") -> 0.13805 | N31: =IFERROR((SUMIFS(qPPTO[Presupuesto],qPPTO[Línea],"Ingresos operacionales",qPPTO[Mes],"Jul"))/(SUMIFS(qPPTO[Real],qPPTO[Línea],"Ingresos operacionales",qPPTO[Mes],"Jul"))-1,"") -> 0.13805 | O31: =IFERROR((SUMIFS(qPPTO[Presupuesto],qPPTO[Línea],"Ingresos operacionales",qPPTO[Mes],"Ago"))/(SUMIFS(qPPTO[Real],qPPTO[Línea],"Ingresos operacionales",qPPTO[Mes],"Ago"))-1,"") -> 0.13805 | P31: =IFERROR((SUMIFS(qPPTO[Presupuesto],qPPTO[Línea],"Ingresos operacionales",qPPTO[Mes],"Sep"))/(SUMIFS(qPPTO[Real],qPPTO[Línea],"Ingresos operacionales",qPPTO[Mes],"Sep"))-1,"") -> 0.13805 | Q31: =IFERROR((SUMIFS(qPPTO[Presupuesto],qPPTO[Línea],"Ingresos operacionales",qPPTO[Mes],"Oct"))/(SUMIFS(qPPTO[Real],qPPTO[Línea],"Ingresos operacionales",qPPTO[Mes],"Oct"))-1,"") -> 0.13805 | R31: =IFERROR((SUMIFS(qPPTO[Presupuesto],qPPTO[Línea],"Ingresos operacionales",qPPTO[Mes],"Nov"))/(SUMIFS(qPPTO[Real],qPPTO[Línea],"Ingresos operacionales",qPPTO[Mes],"Nov"))-1,"") -> 0.13805 | S31: =IFERROR((SUMIFS(qPPTO[Presupuesto],qPPTO[Línea],"Ingresos operacionales",qPPTO[Mes],"Dic"))/(SUMIFS(qPPTO[Real],qPPTO[Línea],"Ingresos operacionales",qPPTO[Mes],"Dic"))-1,"") -> 0.13805
B32: Utilidad bruta | C32: =C9 -> 4370 | D32: =D9 -> 5123.971 | E32: =F9 -> 0.17253341 | H32: =IFERROR((SUMIFS(qPPTO[Presupuesto],qPPTO[Línea],"Ingresos operacionales",qPPTO[Mes],"Ene")-SUMIFS(qPPTO[Presupuesto],qPPTO[Línea],"Costo de ventas",qPPTO[Mes],"Ene"))/(SUMIFS(qPPTO[Real],qPPTO[Línea],"Ingresos operacionales",qPPTO[Mes],"Ene")-SUMIFS(qPPTO[Real],qPPTO[Línea],"Costo de ventas",qPPTO[Mes],"Ene"))-1,"") -> 0.17253962 | I32: =IFERROR((SUMIFS(qPPTO[Presupuesto],qPPTO[Línea],"Ingresos operacionales",qPPTO[Mes],"Feb")-SUMIFS(qPPTO[Presupuesto],qPPTO[Línea],"Costo de ventas",qPPTO[Mes],"Feb"))/(SUMIFS(qPPTO[Real],qPPTO[Línea],"Ingresos operacionales",qPPTO[Mes],"Feb")-SUMIFS(qPPTO[Real],qPPTO[Línea],"Costo de ventas",qPPTO[Mes],"Feb"))-1,"") -> 0.17252319 | J32: =IFERROR((SUMIFS(qPPTO[Presupuesto],qPPTO[Línea],"Ingresos operacionales",qPPTO[Mes],"Mar")-SUMIFS(qPPTO[Presupuesto],qPPTO[Línea],"Costo de ventas",qPPTO[Mes],"Mar"))/(SUMIFS(qPPTO[Real],qPPTO[Línea],"Ingresos operacionales",qPPTO[Mes],"Mar")-SUMIFS(qPPTO[Real],qPPTO[Línea],"Costo de ventas",qPPTO[Mes],"Mar"))-1,"") -> 0.17254256 | K32: =IFERROR((SUMIFS(qPPTO[Presupuesto],qPPTO[Línea],"Ingresos operacionales",qPPTO[Mes],"Abr")-SUMIFS(qPPTO[Presupuesto],qPPTO[Línea],"Costo de ventas",qPPTO[Mes],"Abr"))/(SUMIFS(qPPTO[Real],qPPTO[Línea],"Ingresos operacionales",qPPTO[Mes],"Abr")-SUMIFS(qPPTO[Real],qPPTO[Línea],"Costo de ventas",qPPTO[Mes],"Abr"))-1,"") -> 0.17254256 | L32: =IFERROR((SUMIFS(qPPTO[Presupuesto],qPPTO[Línea],"Ingresos operacionales",qPPTO[Mes],"May")-SUMIFS(qPPTO[Presupuesto],qPPTO[Línea],"Costo de ventas",qPPTO[Mes],"May"))/(SUMIFS(qPPTO[Real],qPPTO[Línea],"Ingresos operacionales",qPPTO[Mes],"May")-SUMIFS(qPPTO[Real],qPPTO[Línea],"Costo de ventas",qPPTO[Mes],"May"))-1,"") -> 0.17252845 | M32: =IFERROR((SUMIFS(qPPTO[Presupuesto],qPPTO[Línea],"Ingresos operacionales",qPPTO[Mes],"Jun")-SUMIFS(qPPTO[Presupuesto],qPPTO[Línea],"Costo de ventas",qPPTO[Mes],"Jun"))/(SUMIFS(qPPTO[Real],qPPTO[Línea],"Ingresos operacionales",qPPTO[Mes],"Jun")-SUMIFS(qPPTO[Real],qPPTO[Línea],"Costo de ventas",qPPTO[Mes],"Jun"))-1,"") -> 0.17252845 | N32: =IFERROR((SUMIFS(qPPTO[Presupuesto],qPPTO[Línea],"Ingresos operacionales",qPPTO[Mes],"Jul")-SUMIFS(qPPTO[Presupuesto],qPPTO[Línea],"Costo de ventas",qPPTO[Mes],"Jul"))/(SUMIFS(qPPTO[Real],qPPTO[Línea],"Ingresos operacionales",qPPTO[Mes],"Jul")-SUMIFS(qPPTO[Real],qPPTO[Línea],"Costo de ventas",qPPTO[Mes],"Jul"))-1,"") -> 0.17252845 | O32: =IFERROR((SUMIFS(qPPTO[Presupuesto],qPPTO[Línea],"Ingresos operacionales",qPPTO[Mes],"Ago")-SUMIFS(qPPTO[Presupuesto],qPPTO[Línea],"Costo de ventas",qPPTO[Mes],"Ago"))/(SUMIFS(qPPTO[Real],qPPTO[Línea],"Ingresos operacionales",qPPTO[Mes],"Ago")-SUMIFS(qPPTO[Real],qPPTO[Línea],"Costo de ventas",qPPTO[Mes],"Ago"))-1,"") -> 0.17252986 | P32: =IFERROR((SUMIFS(qPPTO[Presupuesto],qPPTO[Línea],"Ingresos operacionales",qPPTO[Mes],"Sep")-SUMIFS(qPPTO[Presupuesto],qPPTO[Línea],"Costo de ventas",qPPTO[Mes],"Sep"))/(SUMIFS(qPPTO[Real],qPPTO[Línea],"Ingresos operacionales",qPPTO[Mes],"Sep")-SUMIFS(qPPTO[Real],qPPTO[Línea],"Costo de ventas",qPPTO[Mes],"Sep"))-1,"") -> 0.17252845 | Q32: =IFERROR((SUMIFS(qPPTO[Presupuesto],qPPTO[Línea],"Ingresos operacionales",qPPTO[Mes],"Oct")-SUMIFS(qPPTO[Presupuesto],qPPTO[Línea],"Costo de ventas",qPPTO[Mes],"Oct"))/(SUMIFS(qPPTO[Real],qPPTO[Línea],"Ingresos operacionales",qPPTO[Mes],"Oct")-SUMIFS(qPPTO[Real],qPPTO[Línea],"Costo de ventas",qPPTO[Mes],"Oct"))-1,"") -> 0.17252986 | R32: =IFERROR((SUMIFS(qPPTO[Presupuesto],qPPTO[Línea],"Ingresos operacionales",qPPTO[Mes],"Nov")-SUMIFS(qPPTO[Presupuesto],qPPTO[Línea],"Costo de ventas",qPPTO[Mes],"Nov"))/(SUMIFS(qPPTO[Real],qPPTO[Línea],"Ingresos operacionales",qPPTO[Mes],"Nov")-SUMIFS(qPPTO[Real],qPPTO[Línea],"Costo de ventas",qPPTO[Mes],"Nov"))-1,"") -> 0.17253233 | S32: =IFERROR((SUMIFS(qPPTO[Presupuesto],qPPTO[Línea],"Ingresos operacionales",qPPTO[Mes],"Dic")-SUMIFS(qPPTO[Presupuesto],qPPTO[Línea],"Costo de ventas",qPPTO[Mes],"Dic"))/(SUMIFS(qPPTO[Real],qPPTO[Línea],"Ingresos operacionales",qPPTO[Mes],"Dic")-SUMIFS(qPPTO[Real],qPPTO[Línea],"Costo de ventas",qPPTO[Mes],"Dic"))-1,"") -> 0.17254582
B33: Utilidad operativa | C33: =C12 -> 980 | D33: =D12 -> 1484.611 | E33: =F12 -> 0.51490918 | H33: =IFERROR((SUMIFS(qPPTO[Presupuesto],qPPTO[Línea],"Ingresos operacionales",qPPTO[Mes],"Ene")-SUMIFS(qPPTO[Presupuesto],qPPTO[Línea],"Costo de ventas",qPPTO[Mes],"Ene")-SUMIFS(qPPTO[Presupuesto],qPPTO[Línea],"Gastos de administración",qPPTO[Mes],"Ene")-SUMIFS(qPPTO[Presupuesto],qPPTO[Línea],"Gastos de ventas",qPPTO[Mes],"Ene"))/(SUMIFS(qPPTO[Real],qPPTO[Línea],"Ingresos operacionales",qPPTO[Mes],"Ene")-SUMIFS(qPPTO[Real],qPPTO[Línea],"Costo de ventas",qPPTO[Mes],"Ene")-SUMIFS(qPPTO[Real],qPPTO[Línea],"Gastos de administración",qPPTO[Mes],"Ene")-SUMIFS(qPPTO[Real],qPPTO[Línea],"Gastos de ventas",qPPTO[Mes],"Ene"))-1,"") -> 1.5383227 | I33: =IFERROR((SUMIFS(qPPTO[Presupuesto],qPPTO[Línea],"Ingresos operacionales",qPPTO[Mes],"Feb")-SUMIFS(qPPTO[Presupuesto],qPPTO[Línea],"Costo de ventas",qPPTO[Mes],"Feb")-SUMIFS(qPPTO[Presupuesto],qPPTO[Línea],"Gastos de administración",qPPTO[Mes],"Feb")-SUMIFS(qPPTO[Presupuesto],qPPTO[Línea],"Gastos de ventas",qPPTO[Mes],"Feb"))/(SUMIFS(qPPTO[Real],qPPTO[Línea],"Ingresos operacionales",qPPTO[Mes],"Feb")-SUMIFS(qPPTO[Real],qPPTO[Línea],"Costo de ventas",qPPTO[Mes],"Feb")-SUMIFS(qPPTO[Real],qPPTO[Línea],"Gastos de administración",qPPTO[Mes],"Feb")-SUMIFS(qPPTO[Real],qPPTO[Línea],"Gastos de ventas",qPPTO[Mes],"Feb"))-1,"") -> 0.94264633 | J33: =IFERROR((SUMIFS(qPPTO[Presupuesto],qPPTO[Línea],"Ingresos operacionales",qPPTO[Mes],"Mar")-SUMIFS(qPPTO[Presupuesto],qPPTO[Línea],"Costo de ventas",qPPTO[Mes],"Mar")-SUMIFS(qPPTO[Presupuesto],qPPTO[Línea],"Gastos de administración",qPPTO[Mes],"Mar")-SUMIFS(qPPTO[Presupuesto],qPPTO[Línea],"Gastos de ventas",qPPTO[Mes],"Mar"))/(SUMIFS(qPPTO[Real],qPPTO[Línea],"Ingresos operacionales",qPPTO[Mes],"Mar")-SUMIFS(qPPTO[Real],qPPTO[Línea],"Costo de ventas",qPPTO[Mes],"Mar")-SUMIFS(qPPTO[Real],qPPTO[Línea],"Gastos de administración",qPPTO[Mes],"Mar")-SUMIFS(qPPTO[Real],qPPTO[Línea],"Gastos de ventas",qPPTO[Mes],"Mar"))-1,"") -> 0.59219319 | K33: =IFERROR((SUMIFS(qPPTO[Presupuesto],qPPTO[Línea],"Ingresos operacionales",qPPTO[Mes],"Abr")-SUMIFS(qPPTO[Presupuesto],qPPTO[Línea],"Costo de ventas",qPPTO[Mes],"Abr")-SUMIFS(qPPTO[Presupuesto],qPPTO[Línea],"Gastos de administración",qPPTO[Mes],"Abr")-SUMIFS(qPPTO[Presupuesto],qPPTO[Línea],"Gastos de ventas",qPPTO[Mes],"Abr"))/(SUMIFS(qPPTO[Real],qPPTO[Línea],"Ingresos operacionales",qPPTO[Mes],"Abr")-SUMIFS(qPPTO[Real],qPPTO[Línea],"Costo de ventas",qPPTO[Mes],"Abr")-SUMIFS(qPPTO[Real],qPPTO[Línea],"Gastos de administración",qPPTO[Mes],"Abr")-SUMIFS(qPPTO[Real],qPPTO[Línea],"Gastos de ventas",qPPTO[Mes],"Abr"))-1,"") -> 0.59219319 | L33: =IFERROR((SUMIFS(qPPTO[Presupuesto],qPPTO[Línea],"Ingresos operacionales",qPPTO[Mes],"May")-SUMIFS(qPPTO[Presupuesto],qPPTO[Línea],"Costo de ventas",qPPTO[Mes],"May")-SUMIFS(qPPTO[Presupuesto],qPPTO[Línea],"Gastos de administración",qPPTO[Mes],"May")-SUMIFS(qPPTO[Presupuesto],qPPTO[Línea],"Gastos de ventas",qPPTO[Mes],"May"))/(SUMIFS(qPPTO[Real],qPPTO[Línea],"Ingresos operacionales",qPPTO[Mes],"May")-SUMIFS(qPPTO[Real],qPPTO[Línea],"Costo de ventas",qPPTO[Mes],"May")-SUMIFS(qPPTO[Real],qPPTO[Línea],"Gastos de administración",qPPTO[Mes],"May")-SUMIFS(qPPTO[Real],qPPTO[Línea],"Gastos de ventas",qPPTO[Mes],"May"))-1,"") -> 0.51474737 | M33: =IFERROR((SUMIFS(qPPTO[Presupuesto],qPPTO[Línea],"Ingresos operacionales",qPPTO[Mes],"Jun")-SUMIFS(qPPTO[Presupuesto],qPPTO[Línea],"Costo de ventas",qPPTO[Mes],"Jun")-SUMIFS(qPPTO[Presupuesto],qPPTO[Línea],"Gastos de administración",qPPTO[Mes],"Jun")-SUMIFS(qPPTO[Presupuesto],qPPTO[Línea],"Gastos de ventas",qPPTO[Mes],"Jun"))/(SUMIFS(qPPTO[Real],qPPTO[Línea],"Ingresos operacionales",qPPTO[Mes],"Jun")-SUMIFS(qPPTO[Real],qPPTO[Línea],"Costo de ventas",qPPTO[Mes],"Jun")-SUMIFS(qPPTO[Real],qPPTO[Línea],"Gastos de administración",qPPTO[Mes],"Jun")-SUMIFS(qPPTO[Real],qPPTO[Línea],"Gastos de ventas",qPPTO[Mes],"Jun"))-1,"") -> 0.51474737 | N33: =IFERROR((SUMIFS(qPPTO[Presupuesto],qPPTO[Línea],"Ingresos operacionales",qPPTO[Mes],"Jul")-SUMIFS(qPPTO[Presupuesto],qPPTO[Línea],"Costo de ventas",qPPTO[Mes],"Jul")-SUMIFS(qPPTO[Presupuesto],qPPTO[Línea],"Gastos de administración",qPPTO[Mes],"Jul")-SUMIFS(qPPTO[Presupuesto],qPPTO[Línea],"Gastos de ventas",qPPTO[Mes],"Jul"))/(SUMIFS(qPPTO[Real],qPPTO[Línea],"Ingresos operacionales",qPPTO[Mes],"Jul")-SUMIFS(qPPTO[Real],qPPTO[Línea],"Costo de ventas",qPPTO[Mes],"Jul")-SUMIFS(qPPTO[Real],qPPTO[Línea],"Gastos de administración",qPPTO[Mes],"Jul")-SUMIFS(qPPTO[Real],qPPTO[Línea],"Gastos de ventas",qPPTO[Mes],"Jul"))-1,"") -> 0.51474737 | O33: =IFERROR((SUMIFS(qPPTO[Presupuesto],qPPTO[Línea],"Ingresos operacionales",qPPTO[Mes],"Ago")-SUMIFS(qPPTO[Presupuesto],qPPTO[Línea],"Costo de ventas",qPPTO[Mes],"Ago")-SUMIFS(qPPTO[Presupuesto],qPPTO[Línea],"Gastos de administración",qPPTO[Mes],"Ago")-SUMIFS(qPPTO[Presupuesto],qPPTO[Línea],"Gastos de ventas",qPPTO[Mes],"Ago"))/(SUMIFS(qPPTO[Real],qPPTO[Línea],"Ingresos operacionales",qPPTO[Mes],"Ago")-SUMIFS(qPPTO[Real],qPPTO[Línea],"Costo de ventas",qPPTO[Mes],"Ago")-SUMIFS(qPPTO[Real],qPPTO[Línea],"Gastos de administración",qPPTO[Mes],"Ago")-SUMIFS(qPPTO[Real],qPPTO[Línea],"Gastos de ventas",qPPTO[Mes],"Ago"))-1,"") -> 0.46248889 | P33: =IFERROR((SUMIFS(qPPTO[Presupuesto],qPPTO[Línea],"Ingresos operacionales",qPPTO[Mes],"Sep")-SUMIFS(qPPTO[Presupuesto],qPPTO[Línea],"Costo de ventas",qPPTO[Mes],"Sep")-SUMIFS(qPPTO[Presupuesto],qPPTO[Línea],"Gastos de administración",qPPTO[Mes],"Sep")-SUMIFS(qPPTO[Presupuesto],qPPTO[Línea],"Gastos de ventas",qPPTO[Mes],"Sep"))/(SUMIFS(qPPTO[Real],qPPTO[Línea],"Ingresos operacionales",qPPTO[Mes],"Sep")-SUMIFS(qPPTO[Real],qPPTO[Línea],"Costo de ventas",qPPTO[Mes],"Sep")-SUMIFS(qPPTO[Real],qPPTO[Línea],"Gastos de administración",qPPTO[Mes],"Sep")-SUMIFS(qPPTO[Real],qPPTO[Línea],"Gastos de ventas",qPPTO[Mes],"Sep"))-1,"") -> 0.51474737 | Q33: =IFERROR((SUMIFS(qPPTO[Presupuesto],qPPTO[Línea],"Ingresos operacionales",qPPTO[Mes],"Oct")-SUMIFS(qPPTO[Presupuesto],qPPTO[Línea],"Costo de ventas",qPPTO[Mes],"Oct")-SUMIFS(qPPTO[Presupuesto],qPPTO[Línea],"Gastos de administración",qPPTO[Mes],"Oct")-SUMIFS(qPPTO[Presupuesto],qPPTO[Línea],"Gastos de ventas",qPPTO[Mes],"Oct"))/(SUMIFS(qPPTO[Real],qPPTO[Línea],"Ingresos operacionales",qPPTO[Mes],"Oct")-SUMIFS(qPPTO[Real],qPPTO[Línea],"Costo de ventas",qPPTO[Mes],"Oct")-SUMIFS(qPPTO[Real],qPPTO[Línea],"Gastos de administración",qPPTO[Mes],"Oct")-SUMIFS(qPPTO[Real],qPPTO[Línea],"Gastos de ventas",qPPTO[Mes],"Oct"))-1,"") -> 0.46248889 | R33: =IFERROR((SUMIFS(qPPTO[Presupuesto],qPPTO[Línea],"Ingresos operacionales",qPPTO[Mes],"Nov")-SUMIFS(qPPTO[Presupuesto],qPPTO[Línea],"Costo de ventas",qPPTO[Mes],"Nov")-SUMIFS(qPPTO[Presupuesto],qPPTO[Línea],"Gastos de administración",qPPTO[Mes],"Nov")-SUMIFS(qPPTO[Presupuesto],qPPTO[Línea],"Gastos de ventas",qPPTO[Mes],"Nov"))/(SUMIFS(qPPTO[Real],qPPTO[Línea],"Ingresos operacionales",qPPTO[Mes],"Nov")-SUMIFS(qPPTO[Real],qPPTO[Línea],"Costo de ventas",qPPTO[Mes],"Nov")-SUMIFS(qPPTO[Real],qPPTO[Línea],"Gastos de administración",qPPTO[Mes],"Nov")-SUMIFS(qPPTO[Real],qPPTO[Línea],"Gastos de ventas",qPPTO[Mes],"Nov"))-1,"") -> 0.39640656 | S33: =IFERROR((SUMIFS(qPPTO[Presupuesto],qPPTO[Línea],"Ingresos operacionales",qPPTO[Mes],"Dic")-SUMIFS(qPPTO[Presupuesto],qPPTO[Línea],"Costo de ventas",qPPTO[Mes],"Dic")-SUMIFS(qPPTO[Presupuesto],qPPTO[Línea],"Gastos de administración",qPPTO[Mes],"Dic")-SUMIFS(qPPTO[Presupuesto],qPPTO[Línea],"Gastos de ventas",qPPTO[Mes],"Dic"))/(SUMIFS(qPPTO[Real],qPPTO[Línea],"Ingresos operacionales",qPPTO[Mes],"Dic")-SUMIFS(qPPTO[Real],qPPTO[Línea],"Costo de ventas",qPPTO[Mes],"Dic")-SUMIFS(qPPTO[Real],qPPTO[Línea],"Gastos de administración",qPPTO[Mes],"Dic")-SUMIFS(qPPTO[Real],qPPTO[Línea],"Gastos de ventas",qPPTO[Mes],"Dic"))-1,"") -> 0.3739698
